File: Tensile tests/formatted-CSV/Group5-250C-2h_tensile-test.csv
Strain (percent),Stress (MPa),Extension (mm),Time (s)
-0.0006060383,-1.5795844151450829,0.0,0.0
-0.0002357998,-1.6066173050413135,0.0,0.2
2.727738e-05,-1.6020796157066384,0.0,0.4
-0.0001801855,-1.6218198963152153,0.0,0.6
-0.0001262373,-1.5969579594563739,0.0,0.8
-8.33139e-05,-1.5942182623918544,0.0,1.0
2.370052e-05,-1.592917128286664,8e-05,1.2
-0.0001200635,-1.5919052290621856,0.00016,1.4
5.760794e-05,-1.5824526610454743,0.00028,1.6
-9.747473e-05,-1.5850443578055362,0.00048,1.8
0.0001806453,-1.5580436051182738,0.0006800001,2.0
3.007044e-05,-1.5523049990274267,0.00092,2.2
0.0001994609,-1.5341453616704583,0.00116,2.4
0.0003798274,-1.5233667109258056,0.00144,2.6
6.868177e-05,-1.488252581548168,0.0018,2.8
7.71588e-05,-1.4472171714181814,0.00224,3.0
0.0004405865,-1.40124235684142,0.0028,3.2
0.0004124609,-1.3332395998071769,0.00344,3.4
0.000608409,-1.2541664199994929,0.00416,3.6
0.0009392523,-1.1375451400928598,0.00504,3.8
0.001104184,-0.9651408540040426,0.00604,4.0
0.001305914,-0.7481791733971569,0.0072,4.2
0.002061728,-0.40802550679532834,0.00856,4.4
0.002900743,0.19508998418511034,0.01008,4.6
0.003853338,1.1575488612433718,0.01204,4.8
0.006043753,2.4320983060308015,0.01436,5.0
0.009144819,4.484379625009515,0.0172,5.2
0.01261902,7.019058210634035,0.02048,5.4
0.01663186,10.019878555178742,0.02436,5.6
0.02136965,13.36174234415568,0.02884,5.8
0.02604707,17.213158495640336,0.03412,6.0
0.03106999,21.625990544894837,0.04012,6.2
0.03664376,26.457752255947504,0.04684,6.4
0.04275392,31.86209754488638,0.0544,6.6
0.0493871,37.764493458386546,0.0628,6.8
0.05667364,44.23657214380556,0.0718,7.0
0.06456394,50.99760662364792,0.08128,7.2
0.07264059,57.96533410011587,0.09108,7.4
0.08110865,65.1776426511506,0.10148,7.6
0.09140071,72.62802026335598,0.11224,7.8
0.1017479,80.39050937476216,0.12344,8.0
0.1126523,88.300829647421,0.13496,8.2
0.1236662,96.25250543372549,0.14692,8.4
0.1356277,104.38465701986588,0.15924,8.6
0.1478195,112.38009861048859,0.17192,8.8
0.160711,119.7129639809545,0.1848,9.0
0.1743417,126.0493221586056,0.19796,9.2
0.1908281,130.93565792478205,0.21128,9.4
0.2115206,134.16164170394867,0.22448,9.6
0.2368008,136.3029101088437,0.23764,9.8
0.263483,137.91328027874803,0.25048,10.0
0.2897696,139.25970247710225,0.26292,10.2
0.3143399,140.44154833689944,0.27476,10.4
0.3377172,141.54207860084742,0.28612,10.6
0.3590102,142.57321786490536,0.29692,10.8
0.378649,143.55082330455082,0.30716,11.0
0.3963831,144.44009370533564,0.3166,11.2
0.4125438,145.2778177143679,0.32524,11.4
0.4270912,146.08133251016977,0.33316,11.6
0.4398921,146.79224140118234,0.34028,11.8
0.4512627,147.39138891942864,0.34628,12.0
0.4601514,147.95615808123952,0.35128,12.2
0.4671711,148.45534196527493,0.35544,12.4
0.4728778,148.87536682932605,0.35884,12.6
0.4772204,149.17475030234348,0.36144,12.8
0.4803252,149.37188670788126,0.36332,13.0
0.4827182,149.44060113495092,0.36452,13.2
0.4834275,149.35087066464823,0.36504,13.4
0.4840805,149.18498346625174,0.36512,13.6
0.4843034,148.993259643277,0.36512,13.8
0.4842499,148.85287078304847,0.36512,14.0
0.484681,148.74571856262108,0.36512,14.2
0.4846415,148.64063834645606,0.36504,14.4
0.4848009,148.5662153362144,0.365,14.6
0.4846384,148.49432947404924,0.36488,14.8
0.4845946,148.42485390255663,0.36464,15.0
0.485107,148.38721953942309,0.36432,15.2
0.4847763,148.33973258459275,0.36396,15.4
0.4849629,148.270383870504,0.36356,15.6
0.4845967,148.2218820564431,0.3632,15.8
0.4848136,148.1798499699771,0.36276,16.0
0.4846251,148.108133251017,0.36224,16.2
0.4847826,148.04157539981227,0.36168,16.4
0.4845176,147.9680403913974,0.36112,16.6
0.484156,147.88291907343356,0.36052,16.8
0.4842299,147.79124345627227,0.35988,17.0
0.4842541,147.6829072334092,0.35928,17.2
0.4841536,147.60514364486696,0.35868,17.4
0.4839743,147.48302225078865,0.35808,17.6
0.4839964,147.38931691516626,0.35752,17.8
0.4837971,147.26973266916434,0.35696,18.0
0.4835016,147.16384902277517,0.35644,18.2
0.4835137,147.04371506135672,0.35596,18.4
0.4836246,146.91026107253708,0.35552,18.6
0.4833234,146.79989513121285,0.3552,18.8
0.4830158,146.72690983821454,0.35492,19.0
0.4831135,146.62588905897178,0.35468,19.2
0.4831291,146.54571517975697,0.35448,19.4
0.4833212,146.46748644740072,0.35432,19.6
0.4828643,146.4136989081806,0.3542,19.8
0.4824244,146.36375937687643,0.35416,20.0
0.4828323,146.33906446893266,0.35416,20.2
0.4826792,146.30083810458126,0.35416,20.4
0.4828557,146.28870207961575,0.35416,20.6
0.4828915,146.26777060798526,0.35416,20.8
0.4828773,146.25305514914203,0.35416,21.0
0.4826352,146.24979914244398,0.35416,21.2
0.4828169,146.24311798584273,0.35416,21.4
0.4830349,146.21660478844416,0.35416,21.6
0.4823832,146.22874081340967,0.35416,21.8
0.4829819,146.21406764036774,0.35416,22.0
0.4828039,146.20057846976144,0.35424,22.2
0.4828028,146.17152812428643,0.35428,22.4
0.4828829,146.16603097012086,0.3544,22.6
0.483064,146.1706401224597,0.35456,22.8
0.4828483,146.1608298165642,0.35488,23.0
0.4827492,146.17486870258705,0.35528,23.2
0.4828821,146.17343098534374,0.3558,23.4
0.482953,146.17123212367753,0.35632,23.6
0.4829402,146.2344916823829,0.35704,23.8
0.4833067,146.2892517950323,0.35788,24.0
0.483493,146.38008169616808,0.35884,24.2
0.4832941,146.48626134316623,0.35996,24.4
0.4843519,146.6764628772951,0.36128,24.6
0.4841482,146.9609617482642,0.36288,24.8
0.4846012,147.42318784198645,0.36472,25.0
0.4863083,148.5874428084538,0.36684,25.2
0.489495,150.61965613186408,0.3696,25.4
0.4929055,152.88000135314564,0.37308,25.6
0.4961465,154.6372301108734,0.37728,25.8
0.4974182,155.17231464019014,0.3824,26.0
0.498279,155.28111600686722,0.3884,26.2
0.4984337,155.3829402163342,0.39512,26.4
0.4988112,155.46260666593372,0.40268,26.6
0.4992833,155.5356765305346,0.4114,26.8
0.4998608,155.5897177845623,0.42112,27.0
0.5004392,155.66405622320138,0.43192,27.2
0.5399151,155.7479935387296,0.44368,27.4
0.6250966,155.75763470141996,0.45528,27.6
0.6799352,155.82524969765655,0.46636,27.8
0.6857587,157.55528868516532,0.47728,28.0
0.7072006,159.37734157624553,0.48788,28.2
0.7313092,160.37693563255334,0.4982,28.4
0.7518191,161.08226279779777,0.50816,28.6
0.7658036,161.64445252573094,0.5177601,28.8
0.7744568,162.18330049136102,0.52696,29.0
0.780415,162.69111067885626,0.5358,29.2
0.7867648,163.62837546408667,0.54436,29.4
0.794804,164.57151797569415,0.55264,29.6
0.8043935,165.35731502076234,0.5606,29.8
0.8156314,166.0722833486972,0.56832,30.0
0.8289214,166.68407432152435,0.5756,30.2
0.846337,167.04396877616438,0.58244,30.4
0.8645579,167.13446039088996,0.58864,30.6
0.8850867,167.70815185676955,0.59412,30.8
0.9010617,168.4182996033592,0.5988,31.0
0.9109039,169.01114653721575,0.6028,31.2
0.9178994,169.37167527887487,0.60596,31.4
0.9216564,169.60703804876403,0.60836,31.6
0.924544,169.76057779318862,0.61016,31.8
0.925834,169.743790330083,0.6112,32.0
0.9267845,169.57249054912342,0.6116401,32.2
0.9268334,169.33974949891328,0.61172,32.4
0.92765,169.10793873633116,0.61172,32.6
0.9274288,168.938710959634,0.61172,32.8
0.9275052,168.8138409884729,0.61172,33.0
0.9273894,168.68947844692713,0.61172,33.2
0.9275868,168.57289649281566,0.61172,33.4
0.9275799,168.5002917720288,0.6116401,33.6
0.9276533,168.4144515954433,0.6116401,33.8
0.9277691,168.3398594419966,0.6116401,34.0
0.9270877,168.2851416151485,0.61156,34.2
0.9275962,168.24412438791305,0.61144,34.4
0.9277933,168.17765110831087,0.61132,34.6
0.9275806,168.13401216139647,0.61116,34.8
0.9275388,168.10466581531256,0.61104,35.0
0.9271622,168.0474954119906,0.61092,35.2
0.92757,168.00559018292842,0.6108001,35.4
0.9278619,167.97531354921648,0.61072,35.6
0.9276507,167.94376834146632,0.6106,35.8
0.9278241,167.91881971871487,0.61052,36.0
0.9273872,167.8966196730462,0.61044,36.2
0.9274046,167.8633830332451,0.61036,36.4
0.9276872,167.83636240623125,0.61032,36.6
0.9275297,167.81361264514604,0.61028,36.8
0.9277659,167.7923428871054,0.61028,37.0
0.9271588,167.78206743739588,0.61028,37.2
0.9275138,167.74422164525598,0.61028,37.4
0.927435,167.72024559593382,0.61028,37.6
0.9273436,167.71030843263452,0.61028,37.8
0.9273213,167.6841758074474,0.61028,38.0
0.9272527,167.68320323401812,0.61028,38.2
0.9272606,167.64975516521062,0.61028,38.4
0.9272019,167.6477677325508,0.61028,38.6
0.927392,167.62138139255603,0.61028,38.8
0.9271788,167.60057677832938,0.61028,39.0
0.9274234,167.59072418663263,0.61028,39.2
0.9274136,167.58235159798045,0.61028,39.4
0.9272107,167.56953900019454,0.61028,39.6
0.927127,167.5387972226686,0.61036,39.8
0.9274717,167.54970695939718,0.6104,40.0
0.9272895,167.52683034090816,0.61052,40.2
0.9271996,167.51769660783305,0.61068,40.4
0.9274101,167.50200857556052,0.61088,40.6
0.9275133,167.49765313802934,0.61116,40.8
0.9269613,167.50560286866877,0.61152,41.0
0.9272553,167.51524403135917,0.61196,41.2
0.9276335,167.62210025117767,0.6126,41.4
0.9282907,168.13599959405633,0.61364,41.6
0.9300246,169.29002139661546,0.6152,41.8
0.9320063,170.74181981174365,0.61732,42.0
0.9349613,172.43067242881187,0.61988,42.2
0.9381182,174.18993090500075,0.623,42.4
0.9398468,175.40048882386273,0.62676,42.6
0.9413975,175.8115068122426,0.63128,42.8
0.9418231,175.8626726317837,0.63656,43.0
0.9428336,176.01710037803508,0.64252,43.2
0.9425334,176.12471774227652,0.64936,43.4
0.9420174,175.74296152837803,0.657,43.6
0.9393273,175.21908273639878,0.6655201,43.8
0.93852,174.93339986299404,0.675,44.0
0.938076,175.11971110340573,0.6855601,44.2
0.9989954,176.12755089096186,0.6969601,44.4
1.001528,176.1504697952522,0.69716,44.404
1.106982,175.84051487191633,0.708,44.604
1.11295,175.52024221306974,0.7189201,44.804
1.118303,176.18104242957304,0.73044,45.004
1.125715,177.03500418629437,0.74252,45.204
1.103838,177.81107549706962,0.75488,45.404
1.161099,177.04845107109938,0.76788,45.604
1.216075,180.7969604966045,0.78016,45.804
1.240123,181.94819143627953,0.79224,46.004
1.247956,183.02994680446204,0.80456,46.204
1.251294,183.5115397951676,0.81732,46.404
1.253958,184.29767512664597,0.83084,46.604
1.256702,184.86595400996256,0.84524,46.804
1.278173,185.56722173828473,0.86044,47.004
1.349607,186.37982798136045,0.87556,47.204
1.35501,187.56294241519583,0.8906,47.404
1.336844,188.90386745938451,0.90632,47.604
1.417866,189.42148795277524,0.92248,47.804
1.475443,190.02084690002792,0.9378,48.004
1.483878,191.60686044839866,0.95308,48.204
1.487691,192.46830679194542,0.96864,48.404
1.492469,193.32193026225656,0.98448,48.604
1.497979,194.1855331816683,1.00084,48.804
1.524737,195.3908476611724,1.01772,49.004
1.619467,196.73490185465528,1.03376,49.204
1.63191,197.5568955456137,1.04932,49.404
1.60606,198.40552929137456,1.0652,49.604
1.63642,199.23902472027945,1.08168,49.804
1.733007,200.51956564024934,1.09724,50.004
1.740518,200.77704388420455,1.1124,50.204
1.743038,200.7753947379549,1.12748,50.404
1.748085,202.5568109740112,1.1424,50.604
1.751448,203.5918405317863,1.15728,50.804
1.765145,204.60441632908504,1.17236,51.004
1.796898,205.1123956597854,1.1872,51.204
1.808656,205.94398822763296,1.2018,51.404
1.902235,206.93233426080192,1.21572,51.604
1.92591,207.71005471782686,1.22904,51.804
1.930389,207.5662407076952,1.24248,52.004
1.928224,208.69962703923278,1.256,52.204
1.904534,209.0152482599393,1.26976,52.404
1.903984,209.81973562917048,1.28392,52.604
2.0188,211.53916088055954,1.297,52.804
2.036266,212.09179401740488,1.30916,53.004
2.041216,211.57687981529565,1.321,53.204
2.04331,211.60618387557827,1.33276,53.404
2.04966,214.11284388927888,1.3446,53.604
2.051842,213.70140304288628,1.35648,53.804
2.054553,214.36841927217682,1.36884,54.004
2.077728,214.20346236140833,1.3814,54.204
2.151995,216.42617321955638,1.39352,54.404
2.243905,216.37551482963053,1.40456,54.604
2.256454,216.14679093054139,1.41444,54.804
2.253077,215.15447003205264,1.42392,55.004
2.236693,217.7104775758396,1.43324,55.204
2.221761,218.92640579146337,1.44272,55.404
2.214968,217.8022800504047,1.45264,55.604
2.214453,218.32235312026933,1.46288,55.804
2.215592,219.10366787040252,1.47368,56.004
2.216779,219.7586749321313,1.48496,56.204
2.217967,220.72921864296407,1.49692,56.404
2.19756,220.24809079607255,1.50964,56.604
2.301568,220.2917720287882,1.52312,56.804
2.389159,223.3817223852575,1.53552,57.004
2.415157,222.96089409098215,1.54724,57.204
2.421015,223.60410341415562,1.55884,57.404
2.424103,222.7713268438724,1.57052,57.604
2.426644,222.81767208206833,1.58244,57.804
2.427516,222.77339884813483,1.59468,58.004
2.434575,225.66722765829692,1.6074,58.204
2.435631,224.68886107422856,1.62052,58.404
2.437409,225.34978814813564,1.6344,58.604
2.462012,226.09448339436588,1.64908,58.804
2.62534,226.91461651006827,1.66272,59.004
2.652562,226.49184306893434,1.67536,59.204
2.634546,227.45739705521683,1.68768,59.404
2.594696,228.93169151662255,1.70064,59.604
2.591082,229.1453616704583,1.71404,59.804
2.590823,229.5074127009633,1.728,60.004
2.592051,230.37854249300176,1.74268,60.204
2.59341,231.072410206101,1.75812,60.404
2.596632,232.4687296499582,1.77464,60.604
2.587954,231.29301523134566,1.79216,60.804
2.768445,231.241764840202,1.80972,61.004
2.870249,234.34397807904065,1.82512,61.204
2.897891,234.7030691034565,1.83944,61.404
2.906577,234.20367379041468,1.85336,61.604
2.909061,233.31474167604003,1.86716,61.804
2.912808,233.92209263973348,1.881,62.004
2.91617,235.07197043376775,1.89488,62.204
2.920223,236.22865624180716,1.90896,62.404
2.924328,236.83858663937826,1.92324,62.604
2.922363,235.86186920155953,1.9378,62.804
2.92315,236.47340645957905,1.95256,63.004
3.04461,236.18349500604688,1.96708,63.204
3.101941,238.86551423762933,1.97996,63.404
3.094511,238.62495031418354,1.99248,63.604
3.045376,239.2659607756908,2.00572,63.804
3.034473,239.35484552996797,2.01968,64.004
3.035723,241.0082203597676,2.03436,64.204
3.037616,241.83740263694258,2.0498,64.404
3.040324,242.6474717319419,2.06568,64.604
3.097933,242.19353365526925,2.08156,64.804
3.271745,241.70597836658408,2.09588,65.004
3.35747,243.774134621077,2.10784,65.204
3.37604,243.587781094864,2.11872,65.404
3.379669,243.4967820505231,2.12884,65.604
3.385143,245.21493872787397,2.13848,65.804
3.391375,246.26557174631907,2.14752,66.004
3.396903,246.5391185947583,2.15608,66.204
3.402026,246.6948994866504,2.16444,66.404
3.401981,242.95675008245735,2.17248,66.604
3.404659,244.51925272531992,2.18052,66.804
3.404877,244.56301852963816,2.18852,67.004
3.40517,245.19201982358368,2.19656,67.204
3.404436,245.42987745574794,2.20464,67.404
3.40387,245.67103338041156,2.2128,67.604
3.403535,245.82127483233683,2.22144,67.804
3.406408,246.25550772561593,2.23064,68.004
3.408924,247.0570773745592,2.24032,68.204
3.402598,247.68244208959518,2.25084,68.404
3.392893,245.6897237045745,2.26212,68.604
3.393129,246.62246390906864,2.2744,68.804
3.395278,247.05999509484707,2.28784,69.004
3.516798,247.72409360384975,2.30156,69.204
3.583949,248.80060553267427,2.31472,69.404
3.586349,248.600297692041,2.32824,69.604
3.587903,249.83762252310925,2.34212,69.804
3.587831,250.90292871459624,2.35632,70.004
3.584747,251.7570173287214,2.37132,70.204
3.584491,251.7746505078525,2.38736,70.404
3.708918,251.74894074067814,2.40356,70.604
3.923205,250.5114890522061,2.41748,70.804
3.992556,253.64609321482038,2.429,71.004
4.031526,253.8993851644495,2.43868,71.204
4.040504,253.7047436211869,2.44716,71.404
4.043106,253.97888247084396,2.45472,71.604
4.043509,253.73704997335997,2.4614,71.804
4.043642,252.39840836244008,2.46736,72.004
4.042707,252.04210820090836,2.4724,72.204
4.043929,252.7668445489374,2.4768,72.404
4.044505,252.76950855441765,2.48064,72.604
4.044564,252.90913627022323,2.48408,72.804
4.045686,253.29660106729364,2.48716,73.004
4.046073,253.5894302411137,2.49004,73.204
4.046977,253.78009691905655,2.4928,73.404
4.047374,253.8444981943963,2.49556,73.604
4.047886,253.8411576160957,2.49836,73.804
4.048618,253.9117749042227,2.50132,74.004
4.049196,254.05512377054035,2.5046,74.204
4.049969,254.1710714376327,2.50832,74.404
4.051452,254.34926380419986,2.5126,74.604
4.053023,254.96003991779645,2.51756,74.804
4.053631,255.81095709682606,2.52332,75.004
4.051815,255.76892501036005,2.5302,75.204
4.051178,255.30492291298432,2.53836,75.404
4.051631,256.11558400920137,2.54776,75.604
4.052669,256.9634566105393,2.55848,75.804
4.05319,257.06456196138464,2.57056,76.004
4.055658,258.0397993961588,2.58408,76.204
4.05992,258.8223827203302,2.59904,76.404
4.0611,258.6319274713937,2.61536,76.604
4.096895,258.9958390771547,2.63296,76.804
4.110287,258.6855458674087,2.65184,77.004
4.104212,256.4093011848482,2.67252,77.204
4.102374,256.76915335368693,2.69516,77.404
4.251243,257.59262704769,2.71908,77.604
4.336041,257.90604940673023,2.74224,77.804
4.335645,259.46225146520305,2.76576,78.004
4.315947,260.6851145522357,2.79048,78.204
4.293963,261.2503065720593,2.81668,78.404
4.301654,260.78068046311415,2.84464,78.604
4.621466,259.2778008000474,2.8718,78.804
4.842467,262.69318268311866,2.89424,79.004
4.873611,264.07216494845363,2.9142,79.204
4.868942,260.1273648334363,2.92776,79.348
4.869112,260.5853200612299,2.94564,79.548
4.870534,262.4805273885135,2.96244,79.748
4.871361,262.3721911656504,2.97844,79.948
4.873921,264.168957147569,2.9936,80.148
4.875752,264.7173194184857,3.0078,80.348
4.875458,265.4970695939718,3.02112,80.548
4.871372,266.0628536150132,3.0338,80.748
4.856017,266.1041668428575,3.04624,80.948
4.827242,266.31272041473915,3.05876,81.148
4.809822,267.4006917957089,3.07164,81.348
4.800692,264.65799243929877,3.08492,81.548
4.799546,265.0268091980075,3.09872,81.748
4.799595,265.5561005725498,3.11312,81.948
4.841222,265.36699846925404,3.12796,82.148
4.955032,267.2161142731494,3.14164,82.348
5.049367,268.60562570300146,3.15372,82.548
5.079569,266.5327757245673,3.16448,82.748
5.086076,267.93247803252626,3.17468,82.948
5.087047,268.20103515641523,3.1846,83.148
5.087978,268.71383506846075,3.19424,83.348
5.088017,269.089840413386,3.20368,83.548
5.086958,269.45053829825025,3.213,83.748
5.086172,270.0539989682265,3.22236,83.948
5.082614,270.5609211538949,3.23204,84.148
5.065677,270.0807235946314,3.2422,84.348
5.065626,269.0850198320408,3.25308,84.548
5.169733,268.53517755807957,3.26364,84.748
5.285215,268.64304863712863,3.27252,84.948
5.397188,268.07142917551147,3.27928,85.148
5.442505,269.20189778676115,3.2842,85.348
5.46822,269.8730157387752,3.28772,85.548
5.483688,270.16313862131375,3.29008,85.748
5.492256,270.0567898311105,3.29128,85.948
5.496256,269.6660267415408,3.29168,86.148
5.498526,269.20621093849115,3.29172,86.348
5.499982,268.80026724626407,3.29172,86.548
5.500437,268.4785991559755,3.29172,86.748
5.501505,268.1825985470599,3.29164,86.948
5.502129,267.92753059377725,3.29164,87.148
5.502253,267.697707263855,3.2916,87.348
5.502379,267.5032348637975,3.2916,87.548
5.502401,267.33007450758186,3.2916,87.748
5.502968,267.16143873210257,3.29156,87.948
5.502927,267.0037972649544,3.29156,88.148
5.503305,266.87135813536537,3.29156,88.348
5.503289,266.7545647522475,3.29156,88.548
5.503555,266.6286799218559,3.29156,88.748
5.503562,266.5285048586386,3.29156,88.948
5.503316,266.41336062177044,3.29164,89.148
5.503519,266.31403127457867,3.29164,89.348
5.503745,266.2271339529613,3.2918,89.548
5.503695,266.2053567653054,3.29232,89.748
5.504328,266.5060510981623,3.29332,89.948
5.506396,267.5742750099372,3.29512,90.148
5.508867,269.2442258738361,3.29792,90.348
5.512416,271.46845902083004,3.30188,90.548
5.517272,274.1558908349755,3.30724,90.748
5.513675,273.8994274502508,3.31416,90.948
5.510192,272.87293962433296,3.323,91.148
5.510978,273.8477119152931,3.33372,91.348
5.517996,272.989606150047,3.34648,91.548
5.519789,272.2273200104869,3.36112,91.748
5.521962,272.2119702646246,3.37768,91.948
5.521646,271.3106484104768,3.39612,92.148
5.520516,270.3980785331902,3.41672,92.348
5.521988,270.64358989538493,3.4398,92.548
5.524756,271.35183478091733,3.46556,92.748
5.517064,272.7747097079743,3.49404,92.948
5.457794,272.03876762260774,3.52596,93.148
5.478781,274.6341855331817,3.5612,93.348
5.594282,274.7283137268168,3.59856,93.548
5.977694,273.76567746082225,3.6348,93.748
6.451059,273.1982865793324,3.66508,93.948
6.779864,273.3368571501062,3.68788,94.148
6.839097,272.9175511446767,3.70496,94.348
6.840421,272.6583814686705,3.7182,94.548
6.839938,272.39240377865923,3.72776,94.748
6.839202,272.1320923860186,3.73388,94.948
6.837886,271.64796224723665,3.73668,95.148
6.837499,270.9831871654136,3.737,95.348
6.837366,270.4516123576026,3.73672,95.548
6.836647,270.0812310242467,3.7354,95.748
6.836535,269.63723011087336,3.73292,95.948
6.835447,268.8433987635632,3.72928,96.148
6.832929,266.83490777466744,3.72424,96.348
6.824061,262.0483664994968,3.71716,96.548
6.809149,255.81205652765917,3.708,96.748
6.789865,248.28488790034086,3.69692,96.948
6.767824,239.65334100115868,3.684,97.148
6.74426,230.05552125707231,3.66964,97.348
6.717861,219.73533316982827,3.65408,97.548
6.691565,209.19170690865425,3.63772,97.748
6.665307,198.5165718055192,3.6212,97.946
6.639459,187.91446428118368,3.60432,98.142
6.613536,177.31768476780866,3.58724,98.338
6.587412,166.65142968294109,3.56992,98.536
6.562674,156.33246788393396,3.55264,98.736
6.538239,146.44909212384667,3.53616,98.936
6.515367,137.16296102094842,3.5206,99.136
6.494354,128.7931209458488,3.5062,99.336
6.476051,121.0188340958873,3.493,99.536
6.459265,114.14049880331183,3.48124,99.736
6.444983,108.07781433150379,3.4708,99.936
6.432907,103.00093874478829,3.462,100.136
6.422571,98.96492815642365,3.45504,100.336
6.414896,95.85700633441304,3.44976,100.536
6.409442,93.94826755072182,3.44644,100.736
6.406795,93.17401452940133,3.44508,100.936
6.406352,93.21520089984188,3.44496,101.136
6.406169,93.3717429361569,3.44508,101.336
6.40616,93.53213298038786,3.44568,101.536
6.4062,93.76292888373943,3.44736,101.736
6.406314,94.23987043630491,3.45024,101.936
6.408295,95.68316940537709,3.45448,102.136
6.414584,99.8398636705767,3.46088,102.336
6.424627,106.14949722182287,3.47,102.536
6.436653,114.16806914574227,3.48168,102.736
6.451754,123.8719416794229,3.49612,102.936
6.468768,134.5767614150521,3.51248,103.126
6.485164,145.2118095785797,3.52892,103.292
6.502515,155.98999517941868,3.54568,103.446
6.520437,166.7316458479572,3.56288,103.592
6.537978,177.34263339056014,3.5798,103.726
6.556202,188.1258087159494,3.5972,103.856
6.57397,198.8730833960573,3.6148,103.98
6.592052,209.61135120049394,3.63248,104.098
6.610528,220.37532877210495,3.6506,104.214
6.629726,231.2209179401741,3.66884,104.326
6.648082,241.88784959786207,3.68708,104.434
6.667659,252.6974958348486,3.70604,104.542
6.687777,263.4322962035808,3.726,104.652
6.709767,273.4709031401436,3.7568,104.816
6.704301,272.04798592728537,3.79688,105.016
6.703009,273.9191326336443,3.83956,105.216
6.700383,275.3873802254679,3.88584,105.416
6.70506,276.67401030082124,3.93532,105.616
6.709487,276.908865641095,3.98748,105.816
6.715633,277.511818881456,4.04284,106.016
6.739564,278.037981106704,4.10176,106.216
6.92732,278.54900501509604,4.16224,106.416
7.356943,278.6457972142114,4.22016,106.616
7.945573,278.1941848566089,4.27076,106.816
8.307006,278.0681308830121,4.311,107.016
8.31876,277.1967050903648,4.3448,107.216
8.308587,276.3033752526577,4.37368,107.416
8.304623,276.42959836945954,4.398,107.616
8.302309,276.98971609313026,4.41784,107.816
8.299805,277.736652486828,4.43332,108.016
8.298089,278.4561031096979,4.44456,108.216
8.297519,278.85934051064334,4.45176,108.416
8.296794,278.7744306216859,4.45516,108.616
8.295909,277.93937061813386,4.45552,108.816
8.294984,277.19120793619925,4.455,109.016
8.29437,276.583264971288,4.45308,109.216
8.29331,275.77006672699446,4.44952,109.416
8.290054,273.6309548979644,4.44404,109.616
8.281813,268.052189135932,4.43588,109.816
8.268785,260.78042674830647,4.425,110.016
8.251856,251.93296854782108,4.4116,110.216
8.229833,241.40262002824693,4.39572,110.414
8.206512,230.70600373806485,4.37932,110.594
8.182642,220.04659895300358,4.36256,110.762
8.158181,209.3827541588086,4.34564,110.92
8.133766,198.63590233671343,4.32816,111.076
8.108798,187.94182319460774,4.31044,111.23
8.083291,177.22901144253782,4.29272,111.38
8.057815,166.57231294875808,4.27484,111.53
8.031514,155.83011256480302,4.25684,111.678
8.005604,145.09666534171157,4.23832,111.828
7.97978,134.31213687068157,4.21944,111.98
7.953231,123.66233096250942,4.20092,112.13
7.926309,112.95150664309939,4.182,112.286
7.900517,102.24482633221419,4.16316,112.446
7.874358,91.48012990198153,4.14384,112.616
7.847503,80.76757186471927,4.1248,112.79
7.821056,70.12453168475089,4.10572,112.974
7.794561,59.501577260387506,4.08656,113.172
7.770713,49.8758066016593,4.06908,113.372
7.749556,41.500515886775545,4.05344,113.572
7.730915,34.337047436211876,4.04004,113.772
7.715768,28.331038623850887,4.0288,113.972
7.703622,23.703990933924207,4.02004,114.172
7.694876,20.360571027460402,4.01352,114.372
7.689628,18.313240530094806,4.00948,114.572
7.686282,17.59237333288229,4.00784,114.772
7.685614,17.79853352841183,4.0078,114.972
7.68556,18.0772477017667,4.00816,115.172
7.685535,18.360630227582185,4.0096,115.372
7.686232,18.918955033278927,4.0126,115.572
7.688376,20.870533562240475,4.01736,115.772
7.696282,26.13478176297963,4.02484,115.972
7.708172,33.433167291087,4.03536,116.172
7.722311,42.6538146021329,4.049,116.372
7.740559,53.351953181160845,4.06532,116.566
7.758728,64.03630658897356,4.08164,116.734
7.777161,74.65761186708728,4.09824,116.886
7.795934,85.43220317481797,4.11544,117.03
7.814585,96.28367006926418,4.1328,117.164
7.833482,107.1071437632672,4.1506,117.292
7.852973,117.91129284608814,4.16864,117.414
7.872604,128.65700295154895,4.18668,117.53
7.891841,139.36245697419722,4.20492,117.642
7.910784,150.08364131491928,4.2232,117.75
7.930407,160.82516512605397,4.24188,117.856
7.950731,171.592229561158,4.26052,117.958
7.971489,182.47913195707147,4.2794,118.058
7.991923,193.35973376859522,4.2986,118.156
8.012069,204.28186023696964,4.3178,118.252
8.032806,215.27760628536154,4.33748,118.348
8.054198,226.0273335419433,4.35676,118.44
8.07558,236.78386881253016,4.37648,118.532
8.097663,247.5927539050938,4.3966,118.624
8.120275,258.38937611528803,4.41756,118.718
8.145659,269.2566578994105,4.4412,118.822
8.178388,279.8572431349002,4.47896,118.984
8.180515,279.3374660656445,4.5278,119.184
8.193248,279.7209982831965,4.579,119.384
8.205113,279.7238314318818,4.63264,119.584
8.213785,279.80899503564694,4.68884,119.784
8.150978,280.19679811912755,4.748,119.984
8.133134,280.92956876939866,4.81104,120.184
8.187854,280.98141116176015,4.87736,120.384
8.680207,280.8312119956361,4.94272,120.584
9.385575,280.81552396336366,4.99896,120.784
10.10045,281.13448576237073,5.04144,120.984
10.48383,281.3544987863976,5.06932,121.184
10.62899,281.50863053204,5.08488,121.384
10.65244,281.0899588136296,5.09016,121.584
10.6532,279.7482303392168,5.08916,121.784
10.65088,278.0633948732695,5.08268,121.984
10.63399,269.69655709006037,5.06876,122.184
10.58394,258.99964479926933,5.05196,122.342
10.53218,248.23321465118448,5.035041,122.468
10.4843,237.5479309557437,5.01816,122.576
10.43775,226.77460822205123,5.00076,122.676
10.39377,215.91832074625987,4.98304,122.77
10.35101,204.96063191901428,4.96484,122.86
10.30815,194.1848566088479,4.94684,122.944
10.26744,183.40404928833,4.92872,123.024
10.22623,172.57338700811044,4.91036,123.102
10.18505,161.75287332019656,4.89168,123.178
10.14423,150.85527261656085,4.87264,123.252
10.10404,140.07019443011427,4.8536,123.324
10.064,129.10599358947255,4.83424,123.396
10.02334,118.04690341077274,4.8144,123.468
9.984108,107.08088428067626,4.79464,123.538
9.946144,96.1749532741896,4.77504,123.606
9.906307,85.12140253545665,4.75512,123.674
9.86711,73.94530754463267,4.73472,123.742
9.828985,63.01996735536143,4.71468,123.808
9.7921,52.3604779986976,4.69504,123.872
9.755095,41.74252175604476,4.6752,123.936
9.717643,31.029638118112704,4.65528,124.0
9.67848,19.911694561200243,4.63396,124.068
9.639338,8.692662567762998,4.61236,124.136
9.633526,7.044429691398223,4.60916,124.146
nan,nan,2.0,nan
nan,nan,nan,nan
nan,nan,2.33,nan
nan,nan,2.57,nan
nan,nan,20.0,nan
nan,nan,9.97,nan
nan,nan,8.0,nan
nan,nan,10.0,nan
nan,nan,1.0,nan
nan,nan,0.059881,nan
nan,nan,100.0,nan
nan,nan,10.0,nan
nan,nan,10.0,nan
nan,nan,100.0,nan
nan,nan,2.0,nan
nan,nan,nan,nan
nan,nan,10.0,nan
nan,nan,nan,nan
nan,nan,10.0,nan
nan,nan,1.0,nan
nan,nan,100.0,nan
nan,nan,5.0,nan
nan,nan,8.0,nan
nan,nan,10.0,nan
nan,nan,1.0,nan
nan,nan,0.1,nan
nan,nan,100.0,nan
nan,nan,nan,nan
nan,nan,nan,nan
nan,nan,nan,nan
nan,nan,nan,nan
nan,nan,nan,nan
nan,nan,nan,nan
nan,nan,nan,nan
nan,nan,nan,nan
nan,nan,nan,nan
nan,nan,nan,nan
nan,nan,nan,nan
nan,nan,nan,nan
nan,nan,nan,nan
nan,nan,nan,nan
nan,nan,nan,nan
nan,nan,nan,nan
nan,nan,nan,nan
nan,nan,nan,nan
nan,nan,nan,nan
nan,nan,nan,nan
nan,nan,0.0,nan
nan,nan,0.0,nan
nan,nan,0.0,nan
nan,nan,0.0,nan
nan,nan,0.0,nan
nan,nan,0.0,nan
nan,nan,0.0,nan
nan,nan,0.0,nan
nan,nan,0.0,nan
nan,nan,0.0,nan
nan,nan,nan,nan
0.000189059,9.864292177972482,4.60852,0.0
0.0002605981,9.841077273073248,4.60852,0.1
0.0001132326,9.858000050742962,4.60852,0.2
0.0003246646,9.856181761288195,4.60852,0.3
5.605052e-05,9.850477406696381,4.60852,0.4
0.0002430073,9.839411212503068,4.60852,0.5
0.000502532,9.841094187393757,4.60852,0.6
0.0001219791,9.86246543135746,4.60852,0.7
4.411913e-05,9.849864262577913,4.6086,0.8
-8.330344e-05,9.848045973123146,4.60868,0.9
5.859847e-05,9.850008034302244,4.60884,1.0
8.870857e-05,9.863395718985482,4.60908,1.1
-0.0001987703,9.89990105122502,4.60936,1.2
6.320442e-05,9.921991153810374,4.60972,1.3
0.0001192106,9.948622751452518,4.61012,1.4
0.0002414883,10.021481187047016,4.61064,1.5
0.0003369879,10.107114163206282,4.61128,1.6
0.000611923,10.195470344967568,4.61204,1.7
0.0008707862,10.387739654778718,4.61292,1.8
0.00155489,10.850663464221986,4.614,1.9
0.002659015,11.70901025853539,4.61532,2.0
0.005098469,12.867763842257048,4.61684,2.1
0.006800533,14.195339258983621,4.61872,2.2
0.009185916,15.76708557800462,4.621,2.3
0.01212913,17.561022639818006,4.6236,2.4
0.01507717,19.55334353830671,4.62648,2.5
0.01920757,21.75370212190151,4.62972,2.6
0.0234929,24.20529333660344,4.63332,2.7
0.02822481,26.904243803015827,4.63732,2.8
0.03357127,29.863192747139372,4.64176,2.9
0.0388295,33.04349517519008,4.6466,3.0
0.04527568,36.55396091100531,4.65184,3.1
0.05185932,40.302838222981485,4.65752,3.2
0.05937493,44.32503404007002,4.66356,3.3
0.0667773,48.558561606183886,4.67,3.4
0.07499345,52.995526162225254,4.6768,3.5
0.08366304,57.63749228284128,4.68392,3.6
0.09264001,62.41785983102595,4.69144,3.7
0.1017987,67.45705876880662,4.69932,3.8
0.110979,72.77919200290927,4.7076,3.9
0.120787,78.14974247947025,4.71604,3.998
0.1306218,83.49758548074729,4.72452,4.092
0.1399701,88.89845487682148,4.73316,4.184
0.1499108,94.24688987931633,4.74184,4.274
0.1595189,99.55574537181906,4.7504,4.36
0.1698908,104.9682433632435,4.7592,4.446
0.1799582,110.27532285209274,4.76788,4.528
0.1906241,115.65428820310717,4.7768,4.61
0.2010267,120.97498371996653,4.78576,4.69
0.2113607,126.31331241595699,4.79464,4.768
0.2218387,131.6951954872593,4.80368,4.846
0.2320374,137.01889329600908,4.81268,4.922
0.2420299,142.39384149590254,4.82192,4.998
0.2524838,147.73043647404077,4.83112,5.072
0.262882,153.0603080097765,4.84024,5.144
0.2736046,158.4473922346355,4.84948,5.216
0.2841738,163.88082169769038,4.85896,5.288
0.2954304,169.181008600932,4.8682,5.358
0.3065174,174.61143577209646,4.87776,5.43
0.3175292,180.00507429615288,4.8872,5.5
0.3287816,185.40979170014293,4.89676,5.57
0.3392756,190.704016305405,4.906241,5.638
0.3500236,196.0516055918744,4.91584,5.706
0.3610937,201.34604162614278,4.92532,5.772
0.3723706,206.6908400497281,4.93492,5.838
0.3836665,212.03483504308926,4.94456,5.904
0.3958567,217.35688370558935,4.95436,5.97
0.4076356,222.66244090559272,4.9642,6.036
0.4193248,228.03946110974863,4.97416,6.102
0.4313939,233.42460018774898,4.98416,6.168
0.4431718,238.79519295011124,4.99432,6.234
0.4554618,244.10654330488913,5.00452,6.3
0.4685363,249.4940926735621,5.015041,6.368
0.4815939,254.8505196924977,5.0256,6.436
0.4957418,260.19481068646775,5.03656,6.506
0.5108518,265.5503919893779,5.04816,6.58
0.5276672,270.86825435755185,5.060841,6.66
0.5473375,276.2353796842097,5.0758,6.754
0.5680923,280.3439527075599,5.0918,6.854
0.587421,282.6971152626371,5.1078,6.954
0.6047388,283.6794989978265,5.12384,7.054
0.6130708,281.3858325651413,5.14012,7.154
0.6192771,280.9488088089782,5.15668,7.254
0.6265772,281.0921576752958,5.17344,7.354
0.632485,281.36511252251717,5.1902,7.454
0.6363861,281.5395837385723,5.2072,7.554
0.6394784,281.4657527295485,5.22448,7.654
0.6402451,280.88081324053013,5.24196,7.754
0.6406809,280.35676530534585,5.2598,7.854
0.6425299,280.34162698848985,5.27776,7.954
0.6444911,280.4726284008356,5.29596,8.054
0.6474991,280.66612822746384,5.31448,8.154
0.6515674,280.8874521113301,5.3332,8.254
0.6576484,281.34320847745744,5.35224,8.354
0.6700167,281.827423187842,5.3716,8.454
0.7069237,281.8196426004077,5.3912,8.554
0.7890859,281.785687101985,5.41056,8.654
0.8963708,281.8170208807287,5.42932,8.754
1.040239,281.6267770607986,5.44724,8.854
1.19688,281.92108623766313,5.46392,8.954
1.361719,282.1541655742835,5.479,9.054
1.512139,282.2955692937426,5.492441,9.154
1.63459,282.2318445912232,5.50416,9.254
1.719061,281.5387803083481,5.51436,9.354
1.778267,281.70940351648727,5.52308,9.454
1.8306,282.10908891012576,5.53032,9.554
1.881402,282.1682890319089,5.536,9.654
1.920363,282.23810288981167,5.5402,9.754
1.94785,282.26389722858863,5.54304,9.854
1.964583,282.07657112894634,5.54452,9.954
1.973955,281.6103278841031,5.54488,10.054
1.978537,281.0512250196629,5.5448,10.154
1.981803,280.5945383659075,5.544481,10.254
1.983316,280.23548962729296,5.5436,10.354
1.98476,279.8296727924698,5.542081,10.454
1.985274,279.36326040442145,5.53996,10.554
1.985231,278.6256268870039,5.53712,10.654
1.98323,277.113148347048,5.53348,10.754
1.978688,274.1551719763538,5.52884,10.854
1.972786,270.4150774253022,5.52316,10.954
1.965315,266.14061720355545,5.51652,11.054
1.956881,261.3518347809173,5.50896,11.154
1.946916,256.03752442005026,5.50064,11.252
1.936564,250.73518094094368,5.49232,11.34
1.926386,245.44780663548798,5.48396,11.422
1.916353,240.04571095117683,5.47536,11.5
1.90613,234.63841411330904,5.46668,11.574
1.895792,229.33776206625342,5.45816,11.644
1.885471,224.01237282545267,5.449521,11.712
1.875487,218.61505543668548,5.44076,11.778
1.864642,213.2353712270494,5.432001,11.842
1.853869,207.8699796182438,5.42312,11.904
1.842382,202.4209889803202,5.41396,11.966
1.830736,196.98899723450862,5.404881,12.026
1.820622,191.67468687364158,5.39588,12.084
1.80939,186.22836024119823,5.38668,12.142
1.798473,180.78355589760073,5.37744,12.2
1.787673,175.3395972700287,5.367961,12.258
1.776797,169.9282832810399,5.3586,12.314
1.765176,164.4630548954272,5.34916,12.37
1.754339,159.09935471867257,5.33984,12.424
1.742929,153.6931995974392,5.33032,12.478
1.731092,148.2485643970468,5.32072,12.532
1.719045,142.9487580660166,5.31136,12.584
1.707426,137.55300525189656,5.30184,12.636
1.695766,132.12722951887216,5.29228,12.688
1.684606,126.69401148482363,5.28252,12.74
1.673152,121.19508131559587,5.27272,12.792
1.661981,115.85125546543982,5.26324,12.842
1.650399,110.48747071708263,5.25372,12.892
1.638831,105.16034775842968,5.24424,12.942
1.62651,99.71351369637104,5.23428,12.994
1.615327,94.3926490363066,5.22468,13.044
1.603677,89.08235582656056,5.21508,13.094
1.591768,83.7490168551204,5.205401,13.144
1.580223,78.40650186480384,5.19564,13.194
1.568938,73.10530010233165,5.18588,13.244
1.557301,67.77098855746219,5.176041,13.294
1.545353,62.384750048628675,5.16624,13.344
1.533297,57.022868161328795,5.15644,13.394
1.520921,51.54186717184105,5.146241,13.446
1.508725,46.04957587341323,5.136,13.498
1.497357,40.73698231607791,5.12616,13.548
1.485293,35.40614666407314,5.11632,13.598
1.472995,29.945324458953174,5.10612,13.65
1.460655,24.563462530551494,5.09592,13.702
1.448314,19.193229197500063,5.08584,13.754
1.435807,13.867163383878964,5.0758,13.806
1.422009,8.383337702866132,5.0654,13.86
1.409211,3.0496054734741174,5.05512,13.914
1.396782,-2.2565597963515813,5.044841,13.968
1.383811,-7.72488011975339,5.03424,14.024
1.371059,-13.118692015595006,5.02372,14.08
1.357682,-18.57524335478633,5.01292,14.138
1.344523,-23.89732584592746,5.00224,14.196
1.330538,-29.28169109376454,4.99132,14.256
1.315951,-34.66143450352241,4.98028,14.318
1.301604,-40.00308263491286,4.96908,14.382
1.286753,-45.337186979356076,4.95772,14.448
1.271419,-50.76423128641865,4.94592,14.518
1.255741,-56.096766827634625,4.934,14.59
1.239038,-61.38786228360242,4.92176,14.666
1.220587,-66.71079894792928,4.90884,14.748
1.199133,-72.03969791023572,4.89532,14.836
1.166481,-77.39244606446049,4.8808,14.934
1.105834,-81.16746868736418,4.8668,15.034
1.017469,-81.8587146807845,4.85404,15.134
0.9350289,-81.0613313261673,4.84284,15.234
0.8712426,-80.15290545740552,4.83296,15.334
0.82145,-79.37552328679077,4.82444,15.434
0.7818921,-78.69273445362516,4.81736,15.534
0.7515384,-78.16488079632622,4.8116,15.634
0.7275119,-77.72388217484334,4.80704,15.734
0.7098864,-77.3511751224174,4.8038,15.834
0.6983237,-76.96265318031512,4.80188,15.934
0.6921682,-76.5843221163198,4.80116,16.034
0.6900469,-76.1647201102814,4.80112,16.134
0.6889327,-75.83180399685395,4.8014,16.234
0.6884118,-75.54937713014725,4.8022,16.334
0.6886372,-75.26327139872976,4.80376,16.434
0.6900884,-74.84345796368495,4.80612,16.534
0.6967202,-73.86771309929553,4.80948,16.634
0.7097575,-72.077755131382,4.81396,16.734
0.7260996,-69.74438233130081,4.81964,16.834
0.7455205,-66.823406036721,4.82656,16.934
0.7676709,-63.36176348705632,4.8346,17.034
0.7928377,-59.18109317253453,4.84376,17.134
0.8217628,-54.350447806635486,4.85408,17.234
0.8513479,-48.95896585844405,4.8652,17.332
0.8787699,-43.6596246712279,4.87592,17.42
0.9049523,-38.25385857936623,4.8866,17.502
0.9304686,-32.829579763706946,4.89708,17.578
0.9533192,-27.498541139856066,4.90724,17.648
0.9754878,-22.164466395473728,4.91724,17.714
0.9923794,-17.97846806999146,4.92512,17.764