File: Tensile tests/formatted-CSV/Group1-130C-2h_tensile-test.csv
Strain (percent),Stress (MPa),Extension (mm),Time (s)
-4.196304e-05,-0.7104409846412791,-0.00012,0.0
0.0003543064,-0.7106210814222597,-0.00012,0.2
0.0002389621,-0.7147170208289501,-0.00012,0.4
0.0004990871,-0.7056650536503262,-0.00012,0.6
-5.508259e-05,-0.7113359983168526,-3.999999e-05,0.8
0.000330358,-0.7130927835051546,-3.999999e-05,1.0
0.0002471205,-0.7047792972859246,-3.999999e-05,1.2
0.0002303015,-0.7220054702293289,-3.999999e-05,1.4
0.0002001057,-0.69908857563644,-3.999999e-05,1.6
-1.299213e-07,-0.7207401641068798,0.0,1.8
0.000161727,-0.7168887018725016,8e-05,2.0
3.152363e-05,-0.6955325057858195,0.00024,2.2
0.0001049981,-0.707690300862613,0.00048,2.4
5.634179e-05,-0.6848419945297706,0.00076,2.6
0.000124855,-0.6472093414685461,0.00116,2.8
0.0003173242,-0.5762974963181149,0.0016,3.0
0.0003553232,-0.4714954765411319,0.0022,3.2
0.0004148941,-0.27527090258783926,0.003,3.4
0.001415092,0.1555725646959815,0.00392,3.6
0.002568351,0.9576663160109403,0.00516,3.8
0.003762856,2.060127498422049,0.00676,4.0
0.00634197,3.5207532084998943,0.00876,4.2
0.008505852,5.199718072796128,0.01112,4.4
0.01090342,7.097849779086892,0.01392,4.6
0.01443437,9.366888281085629,0.01716,4.8
0.01808429,11.973583000210395,0.0208,5.0
0.02256928,15.04275194613928,0.02504,5.2
0.02741204,18.39444982116558,0.02976,5.4
0.0328615,22.126198190616453,0.03504,5.6
0.03872798,26.246661056175043,0.04084,5.8
0.04517496,30.793932253313695,0.04732,6.0
0.0524947,35.85300652219651,0.05456,6.2
0.06017093,41.29576688407322,0.0624,6.4
0.06813601,47.0918156953503,0.07084,6.6
0.07698891,53.351988217967595,0.07992001,6.8
0.08722645,59.920639596044595,0.08944,7.0
0.09690636,66.8124552913949,0.09948,7.2
0.1080935,73.91083526193982,0.11,7.4
0.1189561,81.26644224700188,0.12084,7.6
0.130721,88.70759520302965,0.13188,7.8
0.1424161,96.28895434462444,0.14316,8.0
0.153258,103.86686303387334,0.15448,8.2
0.1641789,111.47498422049232,0.16588,8.4
0.1754485,119.08302124973699,0.17728,8.6
0.1872049,126.69804334104775,0.18884,8.8
0.1983308,134.22823479907424,0.20048,9.0
0.2099835,141.89105827898172,0.21224,9.2
0.2215833,149.59545550178834,0.224,9.4
0.2329792,157.24982116557962,0.23576,9.6
0.2445434,164.84161582158634,0.24752,9.8
0.2554399,172.3304018514622,0.25896,10.0
0.2664272,179.59171049863247,0.2702,10.2
0.2775204,186.66286555859455,0.28116,10.4
0.2882608,193.48196928255837,0.29188,10.6
0.2984672,200.1794235219861,0.30232,10.8
0.3082153,206.71777824531873,0.31248,11.0
0.3184861,213.1304018514622,0.32252,11.2
0.327969,219.33288449400376,0.33232,11.4
0.3365681,225.37454239427726,0.34196,11.6
0.3460685,231.3380601725226,0.35132,11.8
0.3545586,236.9590153587208,0.36024,12.0
0.3621753,242.3094045865769,0.36876,12.2
0.3698975,247.41413843888068,0.37696,12.4
0.3768175,252.1938565116768,0.38468,12.6
0.3835888,256.67999158426255,0.39176,12.8
0.3900941,260.87229118451506,0.39844,13.0
0.3961548,264.80063118030716,0.40476,13.2
0.4019005,268.436019356196,0.41056,13.4
0.4068819,271.80597517357455,0.41596,13.6
0.4118851,274.84969492951814,0.421,13.8
0.4165027,277.7720176730486,0.42572,14.0
0.4212325,280.4249947401641,0.43008,14.2
0.4252139,282.8257942352198,0.434,14.4
0.4281302,285.03719755943615,0.4376,14.6
0.4314745,286.99974752787716,0.44084,14.8
0.434622,288.8724174205764,0.44392,15.0
0.4375427,290.56301283399955,0.44672,15.2
0.4395058,292.0848727119714,0.4492,15.4
0.4417486,293.44313065432357,0.45152,15.6
0.44376,294.70086261308643,0.4536,15.8
0.4453515,295.76217126025665,0.4554,16.0
0.4464149,296.73511466442244,0.45708,16.2
0.448193,297.56398064380386,0.45852,16.4
0.4490012,298.39145802650955,0.45992,16.6
0.4503635,299.0292026088786,0.46104,16.8
0.4512645,299.5766463286345,0.46204,17.0
0.4521176,300.1382284872712,0.46304,17.2
0.4528472,300.6825583841784,0.46404,17.4
0.4535113,301.2703134862192,0.46504,17.6
0.4548653,301.82549968440986,0.46604,17.8
0.4554424,302.43442036608457,0.46704,18.0
0.4563346,302.9519040605933,0.46796,18.2
0.4573523,303.5091941931411,0.46896,18.4
0.4581013,304.2003787081843,0.4702,18.6
0.4598373,304.97567851883025,0.47152,18.8
0.46086,305.8213759730697,0.47292,19.0
0.4623435,306.6869766463286,0.47436,19.2
0.4636473,307.66206606353876,0.47604,19.4
0.4651773,308.8185567010309,0.47784,19.6
0.4671648,309.96065642751944,0.47972,19.8
0.4691395,311.26703134862197,0.48176,20.0
0.4711412,312.64270986745214,0.48404,20.2
0.4735649,314.16772564695975,0.48652,20.4
0.4761036,315.8844940037871,0.48924,20.6
0.479159,317.7636860929939,0.49232,20.8
0.4821715,319.78855459709655,0.49564,21.0
0.4857226,321.92501577950765,0.49912,21.2
0.4888963,324.26248685041026,0.50296,21.4
0.4922379,326.609299389859,0.50684,21.6
0.4965633,329.06745213549334,0.51092,21.8
0.5004518,331.60164106879864,0.51516,22.0
0.5043419,334.11554807490006,0.51948,22.2
0.5086463,336.79751735745845,0.52392,22.4
0.5130713,339.4895855249316,0.52844,22.6
0.5176396,342.2791500105197,0.53308,22.8
0.522621,345.1525773195876,0.53792,23.0
0.5273282,348.12114454029035,0.543,23.2
0.5325649,351.1530401851462,0.5482,23.4
0.5377246,354.3284241531664,0.55364,23.6
0.5437487,357.61321270776347,0.55936,23.8
0.549316,361.0142646749422,0.56532,24.0
0.5555778,364.57134441405424,0.57152,24.2
0.5619824,368.3429833789186,0.57812,24.4
0.568907,372.28184304649693,0.58504,24.6
0.5760418,376.2269303597727,0.59212,24.8
0.5836334,380.2689669682306,0.59956,25.0
0.5916887,384.4202398485167,0.60736,25.2
0.6007925,388.7046076162424,0.6154001,25.4
0.6088718,392.9447927624658,0.6236001,25.6
0.618589,397.11201346517987,0.63188,25.8
0.628619,401.2193561960866,0.64028,26.0
0.6387561,405.11108773406266,0.64868,26.2
0.6486162,408.7236271828318,0.65688,26.4
0.6592891,412.2401009888491,0.665,26.6
0.6700516,415.5304439301494,0.67304,26.8
0.6810727,418.5829581317063,0.68096,27.0
0.6918449,421.35998316852516,0.68868,27.2
0.7038683,423.94151062486844,0.69636,27.4
0.7153519,426.3298969072165,0.70372,27.6
0.7280132,428.52345886808337,0.7108,27.8
0.7397186,430.4695981485377,0.7176001,28.0
0.7509911,432.19398274773823,0.7240001,28.2
0.7615317,433.72101830422883,0.73008,28.4
0.7713474,435.1180307174416,0.73588,28.6
0.78127,436.3778666105618,0.7414,28.8
0.7907321,437.51357037660426,0.74652,29.0
0.7998288,438.47717231222384,0.75124,29.2
0.8082705,439.2960235640648,0.75564,29.4
0.8163771,440.05764780138855,0.7596,29.6
0.8238082,440.6379128971176,0.76324,29.8
0.8306481,441.0620660635388,0.76636,30.0
0.8365113,441.3418893330528,0.769,30.2
0.8416533,441.5897328003366,0.7714,30.4
0.8462237,441.7218598779718,0.7734,30.6
0.8496535,441.6982958131706,0.77488,30.8
0.8527355,441.58215863665055,0.77604,31.0
0.8548288,441.4231011992426,0.77696,31.2
0.8566053,441.1916684199453,0.7775601,31.4
0.8584521,440.86766252892903,0.77788,31.6
0.8593916,440.5276667367978,0.778,31.8
0.8597773,440.16074058489374,0.778,32.0
0.8606452,439.81148748159063,0.778,32.2
0.8611769,439.510624868504,0.778,32.4
0.8618356,439.20849989480325,0.778,32.6
0.8621802,438.980854197349,0.778,32.8
0.8628221,438.74184725436567,0.778,33.0
0.8627794,438.5432358510414,0.778,33.2
0.8634289,438.3404165790027,0.778,33.4
0.8636363,438.18725015779506,0.778,33.6
0.863668,438.0155691142436,0.778,33.8
0.8641436,437.85777403745004,0.778,34.0
0.8643975,437.71302335367136,0.778,34.2
0.864492,437.5699558173785,0.778,34.4
0.8647029,437.44287818220073,0.778,34.6
0.8647267,437.3216915632232,0.778,34.8
0.8650711,437.2089206816747,0.778,35.0
0.8652801,437.08563012834,0.778,35.2
0.865583,436.99053229539237,0.778,35.4
0.8654018,436.8760782663581,0.778,35.6
0.8658298,436.7961287607826,0.778,35.8
0.8660437,436.7060803702924,0.77804,36.0
0.8660402,436.59625499684404,0.77812,36.2
0.8658623,436.5339785398695,0.77828,36.4
0.8665214,436.4843256890384,0.77848,36.6
0.8666486,436.4729644435094,0.77884,36.8
0.8667132,436.57647801388595,0.77936,37.0
0.867504,436.96991373869133,0.7800401,37.2
0.8688721,437.5325057858194,0.781,37.4
0.8709041,438.28823900694294,0.78228,37.6
0.8724154,439.26698926993475,0.78384,37.8
0.8743871,440.35093625078895,0.7856001,38.0
0.8769297,441.5905743740795,0.78776,38.2
0.8807277,443.0616452766674,0.79032,38.4
0.8840217,444.6892488954345,0.79332,38.6
0.8884365,446.32190195665896,0.79664,38.8
0.893725,447.94235219861145,0.8003601,39.0
0.9004116,449.4310961498001,0.80444,39.2
0.9082332,450.6050915211445,0.80876,39.4
0.9176904,451.4058489375131,0.8134,39.6
0.9289341,451.90995160950973,0.81828,39.8
0.9419121,452.41489585524926,0.82356,40.0
0.9548475,452.8988007574163,0.82912,40.2
0.9690253,453.3658741847254,0.83476,40.4
0.9820193,453.91752577319585,0.84056,40.6
0.9962326,454.47801388596673,0.84652,40.8
1.00024,454.6282347990742,0.84812,40.854
1.014409,455.1866189774879,0.85424,41.054
1.029063,455.7816116137176,0.86048,41.254
1.045188,456.4287818220072,0.86704,41.454
1.061499,457.1310751104565,0.87396,41.654
1.077595,457.82284872711966,0.88112,41.854
1.094736,458.5049442457396,0.8884801,42.054
1.113014,459.21270776351776,0.89616,42.254
1.131676,459.8729223648221,0.90412,42.454
1.151668,460.56090889964224,0.91248,42.654
1.171522,461.1567431096149,0.9209201,42.854
1.192188,461.82495266147697,0.92956,43.054
1.213147,462.5028403113822,0.93844,43.254
1.234573,463.097832947612,0.9474,43.454
1.257278,463.6797811908268,0.95644,43.654
1.279019,464.2852934988428,0.9656,43.854
1.300686,464.93246370713234,0.97504,44.054
1.323458,465.7050284031138,0.98492,44.254
1.348672,466.33158005470233,0.99504,44.454
1.372453,466.96065642751944,1.00548,44.654
1.3962,467.5442878182201,1.01616,44.854
1.416926,468.1733641910372,1.02692,45.054
1.436678,468.713233747107,1.03768,45.254
1.456804,469.2589943193772,1.04848,45.454
1.476495,469.74963181148746,1.0592,45.654
1.496622,470.3829160530191,1.07012,45.854
1.517248,470.97622554176303,1.08104,46.054
1.537925,471.53671365453397,1.09216,46.254
1.55983,472.0559646539027,1.10344,46.454
1.581106,472.6572690932043,1.11488,46.654
1.602903,473.2122869766463,1.12644,46.854
1.624609,473.7374289922154,1.13812,47.054
1.6475,474.26088786029874,1.14996,47.254
1.672235,474.8209551861982,1.16188,47.454
1.696714,475.30359772775086,1.17376,47.654
1.720523,475.7025036818851,1.18536,47.854
1.745056,476.0896276036188,1.19684,48.054
1.77069,476.6193982747738,1.20824,48.254
1.796313,477.07553124342525,1.21944,48.454
1.821118,477.48243214811697,1.23052,48.654
1.845647,477.85777403745004,1.2414,48.854
1.870871,478.32484746475905,1.25212,49.054
1.894202,478.6762045024195,1.26252,49.254
1.916698,479.0969913738691,1.27292,49.454
1.939473,479.5097832947612,1.28332,49.654
1.962998,479.9166841994529,1.29352,49.854
1.985511,480.24195245108353,1.3034,50.054
2.005676,480.4881127708815,1.3128,50.254
2.025261,480.62991794656006,1.32168,50.454
2.042919,480.8348411529561,1.3302,50.654
2.060661,481.1302335367136,1.33852,50.854
2.078865,481.436566379129,1.34648,51.054
2.096092,481.72859246791495,1.35428,51.254
2.113084,482.0534399326741,1.362,51.454
2.129432,482.3509362507889,1.36956,51.654
2.145539,482.6825163054912,1.37716,51.854
2.161917,483.0452345886808,1.38464,52.054
2.178629,483.35240900483905,1.39204,52.254
2.194231,483.6465390279823,1.39936,52.454
2.210136,483.9671786240269,1.40676,52.654
2.22587,484.2857142857142,1.41416,52.854
2.242247,484.63622974963175,1.42172,53.054
2.259338,485.00483904902165,1.42936,53.254
2.27653,485.3633494634967,1.43712,53.454
2.294125,485.65916263412583,1.44488,53.654
2.310811,485.85735325057857,1.45248,53.854
2.327539,486.02019776982957,1.46,54.054
2.343949,486.25667999158424,1.46756,54.254
2.360773,486.5811066694719,1.47528,54.454
2.378843,486.8626130864717,1.483,54.654
2.39709,487.21186618977487,1.49088,54.854
2.41514,487.52577319587624,1.49888,55.054
2.432338,487.84220492320634,1.50708,55.254
2.450152,488.149800126236,1.51552,55.454
2.46856,488.4977908689248,1.52404,55.654
2.487606,488.83021249737004,1.53276,55.854
2.506961,489.1870397643593,1.54184,56.054
2.52699,489.47022932884494,1.55104,56.254
2.546626,489.76015148327366,1.56052,56.454
2.56752,490.10351357037655,1.5702,56.654
2.589014,490.3576688407321,1.57992,56.854
2.610457,490.51714706501156,1.58956,57.054
2.631383,490.75278771302334,1.59936,57.254
2.652321,491.0305070481801,1.60932,57.454
2.674357,491.3465179886387,1.61932,57.654
2.697464,491.64275194613924,1.62948,57.854
2.720083,491.93141173995366,1.63976,58.054
2.74183,492.21965074689666,1.65024,58.254
2.764854,492.5112560488113,1.66076,58.454
2.788271,492.82432148116976,1.67136,58.654
2.812184,493.0666947191247,1.68204,58.854
2.835314,493.31075110456555,1.6928,59.054
2.85863,493.62886597938143,1.70356,59.254
2.88242,493.84220492320634,1.7142,59.454
2.906057,493.9907426888281,1.72452,59.654
2.928072,494.1620029455081,1.73468,59.854
2.950292,494.3774458236902,1.74468,60.054
2.971564,494.705659583421,1.75468,60.254
2.993622,494.9837997054492,1.76464,60.454
3.016025,495.26446454870603,1.77464,60.654
3.037987,495.61413843888073,1.7848,60.854
3.059141,495.91794656006726,1.79488,61.054
3.081674,496.22848727119714,1.805,61.254
3.103859,496.3745003155901,1.81476,61.454
3.124628,496.47254365663787,1.8242,61.654
3.144481,496.5625920471281,1.83332,61.854
3.163492,496.6871449610772,1.84204,62.054
3.181856,496.78140122028196,1.8504,62.254
3.199634,496.9316221333894,1.85852,62.454
3.217579,497.11760993057015,1.86652,62.654
3.234737,497.3965916263412,1.87448,62.854
3.251184,497.72228066484325,1.88244,63.054
3.267702,498.07069219440353,1.89044,63.254
3.284593,498.36566379128965,1.89844,63.454
3.30205,498.6833578792341,1.90656,63.654
3.319943,498.9867452135493,1.91484,63.854
3.337825,499.24047969703344,1.92312,64.054
3.355975,499.59646539027983,1.9316,64.254
3.374546,499.920471281296,1.94016,64.454
3.392715,500.124552913949,1.94872,64.654
3.411538,500.35808962760365,1.95744,64.854
3.430044,500.588680833158,1.96624,65.054
3.448329,500.91100357668836,1.97524,65.254
3.467143,501.0877340626972,1.98412,65.454
3.48627,501.23543025457604,1.99292,65.654
3.505463,501.44834841152954,2.00188,65.854
3.525598,501.6288659793814,2.01084,66.054
3.543778,501.8278981695771,2.01976,66.254
3.562439,502.05007363770244,2.02868,66.454
3.580849,502.28781822007153,2.03772,66.654
3.600186,502.55375552282766,2.04692,66.854
3.620683,502.80117820324,2.05624,67.054
3.641449,503.12097622554177,2.06584,67.254
3.663039,503.4466652640437,2.07564,67.454
3.684137,503.6894592888702,2.08556,67.654
3.705712,503.93099095308224,2.09568,67.854
3.727796,504.11697875026294,2.10592,68.054
3.750191,504.2398485167262,2.11596,68.254
3.771735,504.3349463496739,2.12588,68.454
3.794101,504.5356616873554,2.13592,68.654
3.815498,504.6964022722491,2.14592,68.854
3.838276,504.94845360824746,2.156,69.054
3.85946,505.1415947822428,2.166,69.254
3.88042,505.3444140542815,2.17608,69.454
3.90172,505.4954765411319,2.18604,69.654
3.922355,505.6196086682095,2.19592,69.854
3.944452,505.8935409215232,2.20588,70.054
3.96524,506.1342310119924,2.21576,70.254
3.985805,506.33452556280247,2.22568,70.454
4.007262,506.52850831054064,2.2356,70.654
4.028352,506.65684830633285,2.24536,70.854
4.049378,506.7372185987797,2.25468,71.054
4.070045,506.84241531664213,2.26384,71.254
4.089566,506.97159688617717,2.27292,71.454
4.109145,507.17357458447293,2.28204,71.654
4.129006,507.5261939827477,2.2914,71.854
4.149353,507.82663580896275,2.30076,72.054
4.1695,508.12876078266356,2.31028,72.254
4.189606,508.2996002524721,2.31972,72.454
4.210145,508.38544077424785,2.32896,72.654
4.230423,508.57269093204286,2.33824,72.854
4.251679,508.7245949926362,2.34736,73.054
4.271693,508.89795918367344,2.35644,73.254
4.29145,509.05954134231007,2.36552,73.454
4.311491,509.25562802440555,2.3746,73.654
4.33145,509.3768146433831,2.38348,73.854
4.351897,509.5354512939196,2.39216,74.054
4.371303,509.6810435514412,2.4008,74.254
4.390354,509.76898800757414,2.4092,74.454
4.408838,509.9419314117399,2.41764,74.654
4.427658,510.15022091310743,2.42604,74.854
4.446838,510.29118451504314,2.43428,75.054
4.46553,510.5221965074689,2.4426,75.254
4.484139,510.7325899431937,2.45092,75.454
4.502819,510.92152324847456,2.45928,75.654
4.521333,511.14790658531456,2.46776,75.854
4.539927,511.36545339785397,2.47628,76.054
4.559281,511.61918788133806,2.48484,76.254
4.577565,511.7786661056175,2.49328,76.454
4.595448,511.93604039553964,2.50184,76.654
4.61385,512.1241321270776,2.51048,76.854
4.632595,512.2554176309699,2.519,77.054
4.652244,512.4275194613928,2.52748,77.254
4.670783,512.5895224069009,2.536,77.454
4.689464,512.7313275825793,2.54456,77.654
4.708035,512.9370923627183,2.55328,77.854
4.727531,513.1403324216285,2.562,78.054
4.746664,513.3742899221544,2.57084,78.254
4.768159,513.6334946349674,2.57988,78.454
4.78807,513.7900273511466,2.58892,78.654
4.808027,513.9932674100568,2.59816,78.854
4.828997,514.1455922575216,2.60744,79.054
4.84949,514.2781401220282,2.61664,79.254
4.870879,514.3989059541342,2.6258,79.454
4.892033,514.483904902167,2.63496,79.654
4.912914,514.5752156532716,2.64408,79.854
4.933148,514.6362297496318,2.65296,80.054
4.953492,514.7936040395539,2.66196,80.254
4.974779,514.973280033663,2.67096,80.454
4.995422,515.0540711129812,2.67988,80.654
5.015793,515.185777403745,2.68888,80.854
5.036745,515.3751314958972,2.69792,81.054
5.057546,515.5796339154218,2.70696,81.254
5.078689,515.7285924679151,2.71596,81.454
5.099046,515.8847043972228,2.72508,81.654
5.119538,516.0761624237323,2.73436,81.854
5.140646,516.304228908058,2.74368,82.054
5.162346,516.4860088365243,2.753,82.254
5.185239,516.5011571638964,2.76212,82.454
5.205795,516.5621712602567,2.77112,82.654
5.226583,516.5642751946139,2.77996,82.854
5.246446,516.6046707342731,2.7886,83.054
5.266022,516.6736797811908,2.79712,83.254
5.286108,516.7864506627393,2.80548,83.454
5.305723,516.9004839049021,2.8138,83.654
5.325186,517.0115716389648,2.82212,83.854
5.344058,517.1474857984431,2.8304,84.054
5.36251,517.3843888070692,2.83872,84.254
5.381958,517.553545129392,2.847,84.454
5.400492,517.6999789606564,2.85528,84.654
5.418723,517.8935409215231,2.86368,84.854
5.437467,518.1056175047338,2.87224,85.054
5.456558,518.3252682516305,2.88084,85.254
5.476791,518.5171470650115,2.8894,85.454
5.496253,518.6198190616452,2.89788,85.654
5.515174,518.7527877130234,2.90648,85.854
5.533763,518.7881338102251,2.91488,86.054
5.552365,518.9295181990321,2.92336,86.254
5.571978,519.1016200294551,2.93184,86.454
5.592068,519.2337471070903,2.94036,86.654
5.612783,519.422680412371,2.94908,86.854
5.632559,519.5888912265937,2.95788,87.054
5.652385,519.6898800757416,2.96664,87.254
5.672353,519.9120555438669,2.97548,87.454
5.69391,520.0265095729013,2.98428,87.654
5.714299,520.1089837997055,2.99312,87.854
5.734911,520.2869766463286,3.00216,88.054
5.756265,520.3543025457604,3.01116,88.254
5.777715,520.5377656217125,3.02024,88.454
5.799669,520.663580896276,3.02936,88.654
5.820848,520.74310961498,3.0384,88.854
5.841611,520.6900904691773,3.0472,89.054
5.861641,520.7237534188934,3.05596,89.254
5.882765,520.9072164948453,3.0648,89.454
5.903555,521.0692194403533,3.07368,89.654
5.924524,521.2421628445193,3.08268,89.854
5.94555,521.4037450031559,3.0918,90.054
5.966621,521.5640648011781,3.10104,90.254
5.988418,521.6991373869135,3.11024,90.454
6.010304,521.6549547654113,3.119,90.654
6.031659,521.6132968651377,3.1276,90.854
6.051869,521.6002524721229,3.13604,91.054
6.071074,521.5038922785609,3.14416,91.254
6.090511,521.5737428992215,3.15232,91.454
6.109727,521.6856722070271,3.16036,91.654
6.12785,521.7929728592468,3.16828,91.854
6.146385,521.8813381022512,3.17612,92.054
6.164633,521.9474016410688,3.18392,92.254
6.182805,522.1144540290343,3.1918,92.454
6.201468,522.3092783505155,3.19964,92.654
6.21984,522.4565537555228,3.2074,92.854
6.238177,522.633705028403,3.21528,93.054
6.256529,522.7839259415106,3.2232,93.254
6.274334,522.9168945928886,3.23108,93.454
6.293079,523.1171891436986,3.23916,93.654
6.313239,523.3254786450663,3.24728,93.854
6.332317,523.435724805386,3.25528,94.054
6.35168,523.6027771933516,3.26348,94.254
6.370801,523.7853986955606,3.27188,94.454
6.390561,523.9225752156533,3.2804,94.654
6.411794,524.129181569535,3.28904,94.854
6.43262,524.2478434672838,3.2976,95.054
6.453024,524.3235851041446,3.3062,95.254
6.473204,524.2819272038712,3.31452,95.454
6.493279,524.2688828108562,3.32288,95.654
6.513096,524.2903429413002,3.33116,95.854
6.533206,524.3766042499474,3.3394,96.054
6.552441,524.4923206395961,3.34772,96.254
6.571348,524.5836313907006,3.35608,96.454
6.590946,524.7157584683358,3.36456,96.654
6.610869,524.8912265937303,3.37324,96.854
6.630957,525.0730065221965,3.38196,97.054
6.651583,525.2152324847465,3.39072,97.254
6.672101,525.3907006101409,3.39972,97.454
6.69269,525.48621922996,3.40864,97.654
6.715187,525.5914159478224,3.41772,97.854
6.736765,525.7029244687566,3.42692,98.054
6.758698,525.8438880706922,3.43616,98.254
6.780616,525.8321060382915,3.44524,98.454
6.80223,525.8055964653903,3.45428,98.654
6.824528,525.820324005891,3.46332,98.854
6.846862,525.8363139070061,3.47224,99.054
6.868538,525.9061645276668,3.48112,99.254
6.890182,525.8910162002944,3.48976,99.454
6.91137,525.8358931201346,3.49828,99.654
6.932417,525.8649274142647,3.5068,99.854
6.95371,525.9158426257101,3.51524,100.054
6.974258,526.0079949505575,3.52364,100.254
6.994659,526.1498001262361,3.53208,100.454
7.016303,526.178834420366,3.54036,100.654
7.036833,526.2103934357248,3.54852,100.854
7.056165,526.2112350094677,3.55648,101.054
7.074299,526.2667788764991,3.56432,101.254
7.092463,526.2478434672838,3.57196,101.454
7.10993,526.2284872711971,3.57936,101.654
7.128091,526.3963812329055,3.587,101.854
7.146388,526.6029875867872,3.5948,102.054
7.165226,526.7877130233537,3.60264,102.254
7.183013,527.0035766884073,3.61052,102.454
7.201707,527.1971386492742,3.61848,102.654
7.220888,527.2661476961919,3.62628,102.854
7.240802,527.3145381864085,3.63412,103.054
7.260443,527.3940669051126,3.64192,103.254
7.28015,527.444982116558,3.64964,103.454
7.299887,527.5295602777193,3.6574,103.654
7.320117,527.656637912897,3.66524,103.854
7.339649,527.7050284031137,3.67296,104.054
7.358867,527.786661056175,3.68076,104.254
7.378092,527.8497790868925,3.68856,104.454
7.397482,528.0012623606143,3.69648,104.654
7.417758,528.099305701662,3.70436,104.854
7.436971,528.0706921944035,3.71192,105.054
7.456675,528.0955186198191,3.71952,105.254
7.475725,528.1451714706501,3.72716,105.454
7.494502,528.191037239638,3.73476,105.654
7.512698,528.2663580896276,3.74236,105.854
7.532065,528.4489795918367,3.75008,106.054
7.551738,528.5470229328845,3.75772,106.254
7.571227,528.659793814433,3.76552,106.454
7.590733,528.7969703345256,3.7734,106.654
7.610068,528.8912265937303,3.78136,106.854
7.630137,529.047338523038,3.78936,107.054
7.65077,529.184935830002,3.79752,107.254
7.671175,529.2665684830633,3.8056,107.454
7.691692,529.3696612665684,3.81388,107.654
7.712896,529.4260467073426,3.82216,107.854
7.734232,529.4723332632021,3.83048,108.054
7.75571,529.4794866400167,3.83868,108.254
7.776542,529.3650326109826,3.84656,108.454
7.796595,529.3254786450663,3.85448,108.654
7.816499,529.3460972017673,3.8624,108.854
7.836876,529.3700820534399,3.87036,109.054
7.857874,529.4988428361036,3.87844,109.254
7.878457,529.6187670944666,3.88648,109.454
7.898653,529.6835682726698,3.89452,109.654
7.919224,529.7799284662318,3.90264,109.854
7.939851,529.7946560067326,3.91068,110.054
7.960849,529.7811908268461,3.9186,110.254
7.981423,529.8754470860509,3.9266,110.454
8.001956,529.9503471491689,3.9346,110.654
8.02281,529.9284662318536,3.9424,110.854
8.042835,529.9558173784977,3.95028,111.054
8.063646,529.9936881969281,3.95816,111.254
8.084062,530.0967809804334,3.96616,111.454
8.104306,530.1283399957921,3.97392,111.654
8.124363,530.0727961287608,3.98148,111.854
8.144334,530.0424994740164,3.989,112.054
8.164195,530.0845781611613,3.99652,112.254
8.183417,530.096360193562,4.004,112.454
8.202339,530.1392804544498,4.01152,112.654
8.22107,530.2566799915842,4.019,112.854
8.240841,530.3719755943615,4.02652,113.054
8.261149,530.4977908689249,4.03412,113.254
8.28186,530.5945718493582,4.04176,113.454
8.301716,530.6715758468335,4.04944,113.654
8.321655,530.7485798443088,4.05716,113.854
8.341178,530.8146433831264,4.0648,114.054
8.361358,530.8478855459709,4.07228,114.254
8.381387,530.9168945928886,4.07988,114.454
8.402018,530.947191247633,4.08744,114.654
8.421502,531.0124132127078,4.09504,114.854
8.441133,531.0544918998527,4.10264,115.054
8.461636,531.0641699978961,4.11008,115.254
8.48157,531.0561750473385,4.11744,115.454
8.501428,531.0241952451083,4.12468,115.654
8.520344,531.0507048180096,4.13192,115.854
8.539869,531.051967178624,4.13908,116.054
8.558634,531.0957290132548,4.14632,116.254
8.578322,531.1634756995581,4.15356,116.454
8.597995,531.2337471070903,4.16072,116.654
8.616573,531.3305280875236,4.16792,116.854
8.635421,531.3801809383547,4.17516,117.054
8.654697,531.4134231011992,4.18236,117.254
8.674608,531.4803282137597,4.18964,117.454
8.695028,531.6372817168104,4.19708,117.654
8.714563,531.7391121397012,4.20444,117.854
8.734623,531.8199032190196,4.21184,118.054
8.754579,531.9002735114664,4.21928,118.254
8.775114,531.9629707553124,4.2268,118.454
8.796161,532.0770039974752,4.23448,118.654
8.816571,532.0719545550179,4.242,118.854
8.837778,532.121607405849,4.24956,119.054
8.858132,532.1889333052808,4.25708,119.254
8.879716,532.1843046496949,4.26456,119.454
8.900329,532.1237113402062,4.27192,119.654
8.920889,532.1287607826636,4.2794,119.854
8.941583,532.1498001262361,4.28688,120.054
8.962316,532.2196507468967,4.29432,120.254
8.984044,532.2625710077846,4.30176,120.454
9.004895,532.2718283189564,4.30912,120.654
9.02501,532.2600462865558,4.31644,120.854
9.045535,532.2423732379549,4.3238,121.054
9.065158,532.3050704818008,4.3312,121.254
9.085754,532.3383126446455,4.33852,121.454
9.107061,532.3702924468756,4.34584,121.654
9.127665,532.3829160530191,4.35308,121.854
9.147737,532.3904902167052,4.36036,122.054
9.167182,532.4359351988218,4.36768,122.254
9.188034,532.3782873974332,4.37488,122.454
9.208392,532.4569745423943,4.38212,122.654
9.228583,532.5760572270145,4.38944,122.854
9.248948,532.6677887649905,4.3968,123.054
9.269748,532.7153376814642,4.40412,123.254
9.290696,532.7578371554807,4.41148,123.454
9.31178,532.6610561750473,4.41856,123.654
9.331905,532.5718493583,4.42544,123.854
9.351218,532.5057858194824,4.4322,124.054
9.370853,532.3290553334735,4.43864,124.254
9.389661,532.1577950767935,4.44484,124.454
9.40841,532.0513359983169,4.45092,124.654
9.426541,532.0774247843467,4.45716,124.854
9.444463,532.1691563223227,4.4634,125.054
9.461943,532.1708394698086,4.46952,125.254
9.479669,532.333263202188,4.47576,125.454
9.497947,532.5449189985272,4.48208,125.654
9.517104,532.7220702714075,4.48852,125.854
9.535248,532.8954344624448,4.495,126.054
9.554618,532.9909530822638,4.50148,126.254
9.573188,533.0300862613086,4.50792,126.454
9.591477,533.1159267830843,4.51444,126.654
9.6113,533.2198611403323,4.52104,126.854
9.630632,533.3465179886388,4.52768,127.054
9.649777,533.4163686092993,4.53432,127.254
9.669228,533.5051546391752,4.54108,127.454
9.689142,533.5796339154218,4.54788,127.654
9.709107,533.5863665053649,4.55468,127.854
9.729262,533.6431727330107,4.56156,128.054
9.749278,533.7870818430465,4.5686,128.254
9.769759,533.8682937092361,4.57564,128.454
9.790476,533.9377235430254,4.5828,128.654
9.812357,534.0189354092151,4.59012,128.854
9.834726,534.0631180307174,4.59748,129.054
9.856708,534.0218809173153,4.60484,129.254
9.87837,534.0387123921734,4.6122,129.454
9.900927,533.9713864927414,4.61932,129.654
9.922963,533.8800757416368,4.62648,129.854
9.94542,533.7513149589732,4.63344,130.054
9.966683,533.5455501788343,4.6402,130.254
9.987323,533.3709236271827,4.64684,130.454
10.00772,533.3107511045655,4.65348,130.654
10.02844,533.3082263833368,4.66004,130.854
10.04872,533.281296023564,4.66652,131.054
10.06829,533.2661476961919,4.673,131.254
10.08799,533.3002314327792,4.67944,131.454
10.10769,533.2880286135072,4.6858,131.654
10.12706,533.269093204292,4.69216,131.854
10.14732,533.3742899221544,4.6986,132.054
10.16661,533.4294130023143,4.70492,132.254
10.18558,533.4323585104145,4.71116,132.454
10.20562,533.4664422470019,4.7174,132.654
10.2257,533.5430254576057,4.72368,132.854
10.24582,533.6103513570376,4.73,133.054
10.2655,533.6465390279824,4.73632,133.254
10.2849,533.7605722701452,4.74276,133.454
10.30494,533.8645066273932,4.74916,133.654
10.32542,533.9654954765412,4.75564,133.854
10.34608,534.0117820324006,4.76212,134.054
10.3666,533.9722280664843,4.7684,134.254
10.38702,533.8367346938775,4.77452,134.454
10.40644,533.7584683357879,4.78064,134.654
10.42628,533.6932463707132,4.78668,134.854
10.44564,533.6679991584263,4.79264,135.054
10.46494,533.6069850620661,4.7984,135.254
10.48359,533.5354512939196,4.80412,135.454
10.50196,533.5686934567641,4.80992,135.654
10.52063,533.5947822427939,4.81568,135.854
10.53951,533.6309699137387,4.82144,136.054
10.55859,533.6448558804965,4.8272,136.254
10.57677,533.7555228276877,4.83304,136.454
10.5953,533.8064380391331,4.83876,136.654
10.61348,533.8207447927624,4.84444,136.854
10.63245,533.840100988849,4.85008,137.054
10.65102,533.8657689880075,4.85576,137.254
10.67042,533.9351988217967,4.86152,137.454
10.68834,533.9604460340837,4.8672,137.654
10.70686,534.0441826215022,4.87312,137.854
10.72631,534.221754681254,4.87916,138.054
10.74584,534.3976435935199,4.88528,138.254
10.76723,534.6665264043762,4.89172,138.454
10.78849,534.8777614138439,4.89824,138.654
10.80983,534.9450873132757,4.9048,138.854
10.83226,535.0010519671786,4.91148,139.054
10.8548,535.0498632442667,4.91816,139.254
10.8781,535.0208289501368,4.92488,139.454
10.90076,534.9067957079739,4.9314,139.654
10.92368,534.7502629917947,4.9378,139.854
10.94711,534.6050915211445,4.94412,140.054
10.9696,534.4325689038502,4.950321,140.254
10.99173,534.2827687776141,4.95652,140.454
11.01309,534.2381653692404,4.96276,140.654
11.03464,534.2196507468966,4.96892,140.854
11.05724,534.1434883231642,4.97492,141.054
11.0788,534.0547022932884,4.98076,141.254
11.09986,533.9250999368819,4.986521,141.454
11.12043,533.8691352829791,4.99228,141.654
11.14069,533.7706711550599,4.99788,141.854
11.16063,533.6768356827266,5.00336,142.054
11.18047,533.5872080791079,5.008801,142.254
11.19946,533.5417630969914,5.01408,142.454
11.21783,533.4685461813591,5.01924,142.654
11.23659,533.3915421838839,5.02428,142.854
11.25485,533.3662949715969,5.02924,143.054
11.27231,533.243845992005,5.03396,143.254
11.28853,533.1125604881128,5.03856,143.454
11.30476,533.0666947191247,5.04316,143.654
11.32044,533.1066694719125,5.0478,143.854
11.33668,533.1714706501157,5.05248,144.054
11.35297,533.3359983168525,5.057281,144.254
11.36966,533.5144119503472,5.06208,144.454
11.38671,533.6595834209973,5.06688,144.654
11.40294,533.8594571849358,5.07184,144.854
11.41989,534.090889964233,5.07688,145.054
11.43721,534.3033873343151,5.08208,145.254
11.45525,534.5167262781401,5.08736,145.454
11.47442,534.7334315169367,5.09288,145.654
11.49422,535.0115716389648,5.098601,145.854
11.51388,535.2198611403323,5.10448,146.054
11.53492,535.3919629707553,5.1104,146.254
11.55619,535.5299810645907,5.11648,146.454
11.57907,535.6246581106669,5.12276,146.654
11.60242,535.6654744371975,5.12908,146.854
11.62658,535.6069850620661,5.1354,147.054
11.65105,535.5674310961498,5.14188,147.254
11.67649,535.4698085419735,5.14836,147.454
11.70182,535.3578792341679,5.1548,147.654
11.72667,535.1533768146434,5.16112,147.854
11.75202,534.8537765621712,5.16716,148.054
11.77644,534.5495476541131,5.17304,148.254
11.80104,534.2722491058279,5.17876,148.454
11.82398,534.0214601304439,5.18432,148.654
11.84556,533.8329476120346,5.1898,148.854
11.86768,533.6305491268672,5.19508,149.054
11.88856,533.4664422470019,5.20016,149.254
11.90927,533.2850831054071,5.20504,149.454
11.92818,533.0776351777824,5.20968,149.654
11.94633,532.8188512518409,5.21404,149.854
11.96383,532.5916263412581,5.2182,150.054
11.98023,532.4746475909951,5.22228,150.254
11.99666,532.422049232064,5.22648,150.454
12.01182,532.4140542815064,5.230521,150.654
12.02761,532.4254155270355,5.234521,150.854
12.04259,532.4401430675363,5.238481,151.054
12.0572,532.555017883442,5.242481,151.254
12.07266,532.7128129602356,5.2466,151.454
12.08764,532.9110035766884,5.250761,151.654
12.10325,533.2097622554176,5.25512,151.854
12.11881,533.5783715548074,5.25968,152.054
12.1349,533.9423521986114,5.2644,152.254
12.15167,534.2878182200716,5.26936,152.454
12.16988,534.6921944035346,5.2746,152.654
12.1891,535.0258783925941,5.27996,152.854
12.20924,535.3397853986955,5.28556,153.054
12.23019,535.6031979802231,5.29128,153.254
12.25182,535.7622554176309,5.29712,153.454
12.27523,535.7513149589732,5.30292,153.654
12.29927,535.6494845360825,5.30868,153.854
12.32327,535.4971596886177,5.31448,154.054
12.34803,535.3490427098674,5.32028,154.254
12.37306,535.1937723543025,5.3262,154.454
12.39829,535.0570166210813,5.33208,154.654
12.42428,534.8613507258573,5.33792,154.854
12.44919,534.6614769619188,5.3436,155.054
12.47403,534.3732379549757,5.34916,155.254
12.49914,534.1413843888071,5.3546,155.454
12.52304,533.8910162002945,5.35992,155.654
12.54547,533.6259204712813,5.36508,155.854
12.56762,533.3313696612665,5.369961,156.054
12.58922,533.0948874395119,5.37468,156.254
12.6094,532.872291184515,5.3792,156.454
12.62908,532.650536503261,5.383521,156.654
12.64777,532.5108352619399,5.38776,156.854
12.66558,532.4001683147486,5.39196,157.054
12.68264,532.2520513359983,5.39584,157.254
12.69965,532.1805175678519,5.399761,157.454
12.71557,532.1901956658952,5.40372,157.654
12.7322,532.2541552703556,5.40768,157.854
12.74802,532.3471491689459,5.41164,158.054
12.76422,532.3879654954765,5.41552,158.254
12.77995,532.5243004418262,5.41956,158.454
12.79619,532.7119713864927,5.4236,158.654
12.81257,532.873132758258,5.427561,158.854
12.82882,533.0065221965074,5.431561,159.054
12.84473,533.1298127498421,5.4356,159.254
12.861,533.3078055964653,5.43972,159.454
12.8778,533.5051546391752,5.444,159.654
12.89543,533.7332211235009,5.4484,159.854
12.91319,533.9558173784977,5.45288,160.054
12.93237,534.1922996002525,5.45756,160.254
12.95108,534.3782873974332,5.46236,160.454
12.97107,534.5836313907006,5.46732,160.654
12.99203,534.8226383336839,5.47256,160.854
13.01467,534.9787502629918,5.4778,161.054
13.03868,535.0002103934357,5.48308,161.254
13.06252,534.902167052388,5.48832,161.454
13.08714,534.8196928255838,5.49372,161.654
13.11248,534.6278140122027,5.499,161.854
13.13826,534.3606143488323,5.5042,162.054
13.16299,534.0770039974752,5.509401,162.254
13.18846,533.8220071533768,5.51452,162.454
13.21319,533.656637912897,5.51968,162.654
13.23842,533.4740164106879,5.52472,162.854
13.26299,533.223227435304,5.52956,163.054
13.28628,532.9779086892488,5.53432,163.254
13.30987,532.7624658110667,5.539,163.454
13.33282,532.5289290974121,5.54348,163.654
13.35466,532.2970755312434,5.54776,163.854
13.37474,532.0744792762465,5.55196,164.054
13.39438,531.9330948874394,5.55608,164.254
13.41414,531.774458236903,5.55996,164.454
13.43233,531.5724805386071,5.5636,164.654
13.44958,531.3179044813802,5.56692,164.854
13.46592,531.084788554597,5.57012,165.054
13.48157,530.9084788554597,5.57324,165.254
13.49594,530.7906585314538,5.576281,165.454
13.51015,530.7473174836945,5.57932,165.654
13.52438,530.7527877130234,5.5824,165.854
13.53792,530.8819692825583,5.5856,166.054
13.55151,531.0342941300231,5.5888,166.254
13.56507,531.2480538607196,5.59216,166.454
13.57906,531.5051546391752,5.5956,166.654
13.59349,531.8586156111929,5.599241,166.854
13.60849,532.312644645487,5.60316,167.054
13.62501,532.8306332842415,5.60728,167.254
13.64217,533.2682516305491,5.61152,167.454
13.6603,533.7163896486429,5.61596,167.654
13.67903,534.1068798653481,5.6206,167.854
13.69962,534.4704397222806,5.62556,168.054
13.7228,534.7191247633074,5.6306,168.254
13.747,534.7763517778244,5.63572,168.454
13.77299,534.7262781401221,5.64092,168.654
13.79957,534.5049442457395,5.64612,168.854
13.82722,534.2671996633705,5.65148,169.054
13.85685,534.0117820324006,5.656841,169.254
13.88668,533.5476541131916,5.66204,169.454
13.91574,533.0565958342099,5.66704,169.654
13.94478,532.5726909320429,5.672,169.854
13.97189,532.1384388807069,5.676801,170.054
13.99779,531.7189143698716,5.6814,170.254
14.02258,531.3915421838839,5.68588,170.454
14.0467,531.0675362928677,5.6902,170.654
14.06903,530.7624658110667,5.694201,170.854
14.09011,530.4148958552493,5.6978,171.054
14.10883,530.0315590153588,5.701081,171.254
14.12621,529.682726698927,5.70412,171.454
14.14317,529.3881758889122,5.707,171.654
14.15795,529.1495897328003,5.70972,171.854
14.1718,528.8697664632863,5.71216,172.054
14.1852,528.6543235851041,5.71448,172.254
14.19664,528.4725436566379,5.71672,172.454
14.20808,528.3934357248054,5.719,172.654
14.21869,528.3349463496738,5.72124,172.854
14.2293,528.3803913317904,5.72356,173.054
14.24003,528.5697454239428,5.72604,173.254
14.25066,528.8091731537976,5.7286,173.454
14.26176,529.1975594361455,5.73144,173.654
14.27315,529.7399537134442,5.73456,173.854
14.28585,530.3951188722912,5.738001,174.054
14.29879,531.0570166210814,5.74152,174.254
14.31222,531.7933936461181,5.74536,174.454
14.32775,532.5701662108143,5.7496,174.654
14.34569,533.4252051335998,5.75428,174.854
14.36497,534.1927203871239,5.75932,175.054
14.38817,534.847043972228,5.76484,175.254
14.41455,535.1567431096149,5.77052,175.454
14.44544,535.1075110456553,5.77656,175.654
14.48127,534.6829370923626,5.78288,175.854
14.52051,533.9019566589523,5.78932,176.054
14.56322,532.7292236482222,5.79556,176.254
14.60458,531.4891647380601,5.80152,176.454
14.64279,530.4607616242373,5.8072,176.654
14.67775,529.6297075531243,5.81252,176.854
14.70977,529.006101409636,5.817401,177.054
14.73654,528.467915001052,5.821841,177.254
14.76112,528.0143067536293,5.825841,177.454
14.78177,527.5447086050915,5.82924,177.654
14.80051,527.0995160950978,5.8322,177.854
14.8164,526.6560067325898,5.83468,178.054
14.83041,526.2188091731538,5.83688,178.254
14.8431,525.8291605301914,5.8388,178.454
14.85376,525.4647590995161,5.840521,178.654
14.86378,525.1218177992847,5.84204,178.854
14.87292,524.8436776772564,5.84348,179.054
14.88072,524.6244477172313,5.84488,179.254
14.88854,524.4826425415527,5.84628,179.454
14.89629,524.4350936250789,5.8478,179.654
14.90358,524.550389227856,5.84948,179.854
14.9109,524.8239006942983,5.8514,180.054
14.91839,525.2838207447927,5.8536,180.254
14.92607,525.8695560698505,5.856,180.454
14.93542,526.6450662739322,5.8588,180.654
14.94489,527.6292867662529,5.86208,180.854
14.95612,528.8407321691562,5.86588,181.054
14.96896,530.2432148116978,5.87028,181.254
14.98371,531.749211024616,5.87528,181.454
15.00211,533.2211235009468,5.8808,181.654
15.02415,534.4658110666948,5.88684,181.854
15.05282,535.2308015989901,5.89332,182.054
15.09103,534.9800126236061,5.90004,182.254
15.13922,533.4428781822007,5.9068,182.454
15.19141,531.1411739953713,5.9134,182.654
15.23961,529.1504313065432,5.91976,182.854
15.2814,527.7694087944456,5.92564,183.054
15.317,526.8394698085419,5.93096,183.254
15.34735,526.299600252472,5.93588,183.454
15.37397,525.9739112139702,5.9404,183.654
15.39721,525.6675783715548,5.9444,183.854
15.41783,525.4399326741005,5.94808,184.054
15.43707,525.2720387123921,5.9514,184.254
15.45449,525.0637492110245,5.95436,184.454
15.46981,524.843256890385,5.957001,184.654
15.48372,524.6076162423732,5.95932,184.854
15.49669,524.347149168946,5.9614,185.054
15.50772,524.0559646539028,5.9632,185.254
15.51834,523.8165369240479,5.96488,185.454
15.52744,523.5821586366505,5.9664,185.654
15.53566,523.4668630338733,5.96796,185.854
15.54444,523.4071112981275,5.96956,186.054
15.55271,523.4672838207448,5.97124,186.254
15.56073,523.6978750262991,5.97312,186.454
15.5697,524.0286135072586,5.9752,186.654
15.5784,524.5125184094256,5.97748,186.854
15.58743,525.1739953713444,5.98016,187.054
15.59767,526.0517567851883,5.9832,187.254
15.60935,527.1146644224699,5.98672,187.454
15.62202,528.2444771723121,5.9906,187.654
15.63669,529.4428781822006,5.995,187.854
15.65428,530.646749421418,5.999921,188.054
15.67573,531.6898800757416,6.00536,188.254
15.70326,532.1876709446666,6.01108,188.454
15.73959,531.883021249737,6.017,188.654
15.78467,530.4275194613928,6.023,188.854
15.83367,528.237744582369,6.02888,189.054
15.87992,526.2402693035978,6.03448,189.254
15.91899,524.909741216074,6.03964,189.454
15.95124,524.1009888491479,6.04452,189.654
15.97978,523.6936671575846,6.04912,189.854
16.00525,523.4580265095728,6.05344,190.054
16.02778,523.2787713023353,6.05736,190.254
16.04878,523.1369661266568,6.06092,190.454
16.06725,522.9400378708184,6.06408,190.654
16.0838,522.7296444350936,6.06692,190.854
16.09966,522.5743740795286,6.06956,191.054
16.11427,522.4536082474227,6.07204,191.254
16.12759,522.3000210393435,6.07428,191.454
16.13981,522.11319166842,6.07624,191.654
16.15067,521.9562381653692,6.07812,191.854
16.16141,521.8948032821376,6.08,192.054
16.17148,521.8737639385652,6.08188,192.254
16.18092,521.9187881338102,6.08372,192.454
16.19009,522.0597517357459,6.085761,192.654
16.20047,522.3576688407321,6.08788,192.854
16.20988,522.676625289291,6.09016,193.054
16.21986,523.1159267830843,6.0926,193.254
16.23057,523.6654744371975,6.09528,193.454
16.24216,524.2869766463286,6.09824,193.654
16.25428,525.0410267199663,6.10156,193.854
16.26867,525.904481380181,6.10524,194.054
16.28529,526.8546181359142,6.10944,194.254
16.30572,527.6217126025667,6.11396,194.454
16.33002,528.1237113402062,6.11888,194.654
16.36074,527.9192089206816,6.12392,194.854
16.39936,526.8045444982116,6.12908,195.054
16.44212,525.0031559015358,6.13432,195.254
16.48361,523.1571638964864,6.13932,195.454
16.51997,521.740795287187,6.14396,195.654
16.55113,520.8727119713865,6.14828,195.854
16.57739,520.3492531033032,6.15228,196.054
16.6002,520.0294550810014,6.15596,196.254
16.62133,519.8396802019777,6.15936,196.454
16.63951,519.6679991584263,6.16248,196.654
16.65723,519.5245108352619,6.16528,196.854
16.67321,519.3970124132127,6.16788,197.054
16.68737,519.2888701872502,6.17036,197.254
16.70058,519.2956027771933,6.17284,197.454
16.71498,519.3965916263412,6.17536,197.654
16.72722,519.4714916894592,6.17772,197.854
16.73943,519.6759941089838,6.18032,198.054
16.75246,520.0517567851883,6.18316,198.254
16.76626,520.5365032610982,6.1862,198.454
16.7812,521.0528087523669,6.18948,198.654
16.79663,521.5863665053649,6.19292,198.854
16.81427,522.0816326530612,6.19656,199.054
16.83374,522.4864296233957,6.20048,199.254
16.85642,522.7182831895644,6.20456,199.454
16.88111,522.5811066694719,6.20872,199.654
16.90925,521.9970544918998,6.21288,199.854
16.93999,521.1832526825162,6.21712,200.054
16.97201,520.1413843888071,6.2212,200.254
17.00189,519.0877340626972,6.225,200.454
17.02871,518.1893540921524,6.22844,200.654
17.05134,517.4378287397433,6.23156,200.854
17.07212,516.8584052177572,6.2344,201.054
17.09055,516.5377656217127,6.23712,201.254
17.1071,516.3176940879445,6.23968,201.454
17.12221,516.1805175678519,6.24216,201.654
17.13705,516.120765832106,6.24456,201.854
17.15046,516.1018304228908,6.24688,202.054
17.16295,516.199452977067,6.24924,202.254
17.17592,516.3454660214602,6.25164,202.454
17.18818,516.5693246370713,6.25412,202.654
17.20098,516.8285293498842,6.25672,202.854
17.21418,517.1340206185567,6.2594,203.054
17.22841,517.4832737218599,6.26228,203.254
17.24361,517.9280454449821,6.26544,203.454
17.2608,518.3745003155901,6.26888,203.654
17.27949,518.7157584683358,6.27252,203.854
17.30132,518.8403113822849,6.2764,204.054
17.32614,518.6770460761625,6.28044,204.254
17.35455,518.11613717652,6.2846,204.454
17.38694,517.159688617715,6.288801,204.654
17.42031,515.9528718703976,6.29288,204.854
17.452,514.8769198401009,6.29676,205.054
17.48064,513.9558173784977,6.30044,205.254
17.5062,513.3191668419945,6.30396,205.454
17.50428,503.86661056175046,6.30668,205.616
17.30217,472.2108142225962,6.30696,205.62
16.85586,424.8739743320008,6.30836,205.624
16.27121,369.0875236692615,6.3104,205.628
15.62068,310.41952451083523,6.31232,205.632
14.95764,252.80037870818433,6.31408,205.636
14.2995,198.99844308857564,6.31584,205.64
13.67732,150.7052808752367,6.31768,205.644