File: Tensile Al7075/formatted-CSV/Group3-190C-2h_tensile-test.csv
Strain (percent),Stress (MPa),Extension (mm),Time (s)
-0.0005171917,1.1577208643408206,0.0,0.0
8.787592e-05,1.1610585785485081,0.0,0.2
0.0002407292,1.1561539905782754,0.0,0.4
0.000118574,1.1531431351129924,0.0,0.6
-0.0001442337,1.140036355567693,0.0,0.8
0.0001516485,1.1559534375640061,0.0,1.0
0.0001591209,1.162201304021301,8e-05,1.2
0.0003475967,1.145871594865843,0.00016,1.4
-4.452013e-05,1.159035980064177,0.00032,1.6
0.0002788996,1.1630141837919028,0.00052,1.8
0.0001865606,1.1793387724448694,0.00076,2.0
-2.499391e-05,1.1984851846794564,0.00108,2.2
0.0001101461,1.2098872636034683,0.0014,2.4
9.76268e-05,1.2288403768689835,0.0018,2.6
0.0001239639,1.2813041919847068,0.00224,2.8
0.0003437257,1.3220330955144397,0.00276,3.0
0.0006679786,1.4116811463098247,0.00344,3.2
0.0009023911,1.4959735782071413,0.00424,3.4
0.000844033,1.6281636171229605,0.00512,3.6
0.0007709506,1.7827481736874446,0.00604,3.8
0.001339955,1.9864921144261625,0.00708,4.0
0.00130764,2.3237552911859085,0.008440001,4.2
0.002588481,2.962094626886052,0.00996,4.4
0.004237087,3.9728408547825493,0.0118,4.6
0.006292141,5.35429183450536,0.01396,4.8
0.009221931,7.229031542295352,0.0166,5.0
0.01305061,9.536308629753533,0.01976,5.2
0.01688429,12.233447975694682,0.02352,5.4
0.02165942,15.470360824742269,0.02804,5.6
0.02672651,19.279195398375094,0.03344,5.8
0.03286181,23.55405117088824,0.03944,6.0
0.03971399,28.256076329623813,0.04624,6.2
0.04730876,33.576163207482765,0.05388,6.4
0.05523327,39.474947941558,0.06228,6.6
0.064142,45.68034409776746,0.07116,6.8
0.07361655,52.10380111968322,0.08048,7.0
0.08337833,58.76715368334813,0.09024001,7.2
0.09326673,65.69220659520721,0.1004,7.4
0.1030416,72.68263125554722,0.11072,7.6
0.1145215,79.94653341981292,0.12144,7.8
0.1258574,87.32974329214173,0.13248,8.0
0.1368011,94.93219601283539,0.14392,8.2
0.1479072,102.70776438861199,0.15552,8.4
0.1592406,110.671169864136,0.1674,8.6
0.1712887,118.68684713593227,0.17952,8.8
0.1833641,126.92223663548849,0.19196,9.0
0.1958973,135.23055062470132,0.20452,9.2
0.2087571,143.54569195057007,0.2172,9.4
0.2217876,151.79243189731687,0.22992,9.6
0.2348214,159.89229876425205,0.24228,9.8
0.2471628,167.90281286270223,0.2546,10.0
0.2589215,175.70667201474703,0.26672,10.2
0.270069,183.4495971871373,0.27884,10.4
0.2813259,191.1169096060627,0.29072,10.6
0.2932138,198.66333549532328,0.30256,10.8
0.304312,205.969140438315,0.31404,11.0
0.3159741,213.19229193691538,0.32544,11.2
0.3271626,220.25811599644976,0.3366,11.4
0.3379664,227.14118078787465,0.34752,11.6
0.3488805,233.70067249266063,0.35816,11.8
0.35932,239.96078548508228,0.36824,12.0
0.3685145,245.75130572813546,0.37768,12.2
0.3774195,251.17242438724654,0.38668,12.4
0.3858506,256.2496586331672,0.39516,12.6
0.3943849,260.90086707175533,0.40316,12.8
0.4024309,265.29997610432173,0.41072,13.0
0.4099734,269.3245203795999,0.41772,13.2
0.4171853,272.98068717143445,0.42428,13.4
0.424025,276.311958080153,0.43036,13.6
0.4307317,279.17530040281287,0.43588,13.8
0.4365223,281.7456646412234,0.44092,14.0
0.4418788,284.02522700894383,0.44556,14.2
0.4473698,286.0441131289684,0.44972,14.4
0.4517663,287.86649996586334,0.45348,14.6
0.4558272,289.3769201884345,0.4568,14.8
0.4599902,290.6299498190756,0.45968,15.0
0.4631334,291.6910459479757,0.46216,15.2
0.4656362,292.5579896907216,0.46416,15.4
0.4677438,293.2795538335495,0.466,15.6
0.4702982,293.8883389089916,0.46756,15.8
0.471636,294.3558834573633,0.4688,16.0
0.4729831,294.6657591998362,0.46976,16.2
0.4742369,294.88884242507,0.47052,16.4
0.4744753,295.00716870348873,0.47108,16.6
0.4758182,295.0911876152113,0.47148,16.8
0.475906,295.10057520311324,0.47172,17.0
0.4762057,295.0455724721786,0.4718,17.2
0.4762786,294.94939236703766,0.4718,17.4
0.476556,294.86746432716603,0.4718,17.6
0.476383,294.7958199631324,0.4718,17.8
0.476553,294.7174762750051,0.4718,18.0
0.4765342,294.63823649894175,0.4718,18.2
0.4764832,294.56974977811154,0.4718,18.4
0.4765607,294.5098398989554,0.4718,18.6
0.4768617,294.4634140096948,0.4718,18.8
0.4766594,294.3980422612139,0.4718,19.0
0.4766353,294.3656977538063,0.4718,19.2
0.4766672,294.3126578821602,0.47184,19.4
0.4768966,294.2818495255001,0.47192,19.6
0.476725,294.24758482965797,0.47204,19.8
0.4767064,294.217672560934,0.47216,20.0
0.4766737,294.2198914453472,0.47236,20.2
0.4769472,294.27429678432446,0.47268,20.4
0.4771349,294.4163053867686,0.47308,20.6
0.4775788,294.75946439543935,0.47368,20.8
0.4787176,295.2376339864819,0.47444,21.0
0.4802826,295.9011230968799,0.47552,21.2
0.4814219,296.6316481190688,0.47672,21.4
0.4831973,297.4738854372909,0.4782,21.6
0.4856571,298.4295845565645,0.47996,21.8
0.4883422,299.4219806103639,0.48204,22.0
0.4920351,300.5605243394552,0.48456,22.2
0.4963839,301.6927527821396,0.4874,22.4
0.5010885,302.74766163719534,0.49044,22.6
0.5072705,303.89170990646545,0.49388,22.8
0.5131579,305.0384037686899,0.49748,23.0
0.5204644,306.17327780432856,0.50124,23.2
0.5278258,307.25152761657677,0.50512,23.4
0.5355028,308.34872328804533,0.50924,23.6
0.5442605,309.4096060626749,0.51352,23.8
0.5530766,310.4913122141053,0.51808,24.0
0.5622735,311.504360961289,0.5228,24.2
0.5720955,312.5049071482215,0.52768,24.4
0.5817015,313.45437632279646,0.53268,24.6
0.5924295,314.3573769372568,0.5378,24.8
0.6039824,315.21693862224345,0.54296,25.0
0.6148795,316.02452720693657,0.54812,25.2
0.6263292,316.7658906260668,0.55332,25.4
0.638374,317.5081501331331,0.55852,25.6
0.6505741,318.17705844200174,0.56364,25.8
0.6616331,318.7605823718167,0.5686,26.0
0.6725266,319.3250751007032,0.57344,26.2
0.6833213,319.8805216085205,0.5782,26.4
0.6933574,320.3862565713115,0.58284,26.6
0.7038607,320.8359647026695,0.58728,26.8
0.7136065,321.2612224346282,0.59152,27.0
0.7233185,321.61436642315834,0.5954001,27.2
0.7315843,321.9414811906875,0.59904,27.4
0.7393581,322.24009182767804,0.60244,27.6
0.7465495,322.50699802007233,0.6056,27.8
0.7529991,322.75013654673313,0.60848,28.0
0.7588027,322.95222571174986,0.61108,28.2
0.7641914,323.075416467536,0.61336,28.4
0.7689393,323.2702089165017,0.61552,28.6
0.7734954,323.36920529801324,0.61736,28.8
0.7777099,323.43769201884345,0.619,29.0
0.7803926,323.48565405885165,0.6204,29.2
0.7830155,323.49218269952894,0.6216,29.4
0.7855071,323.50464258892606,0.6226001,29.6
0.7875995,323.4492984911586,0.6234,29.8
0.7888802,323.37074144876084,0.62404,30.0
0.789929,323.29781695910424,0.6245601,30.2
0.7911637,323.2252765071346,0.625,30.4
0.7922136,323.1223544070458,0.62536,30.6
0.792631,323.0327882842903,0.62564,30.8
0.7936504,322.93025022188846,0.6258,31.0
0.7939807,322.83074179012766,0.626,31.2
0.7946297,322.73963951662455,0.6262001,31.4
0.7952256,322.6545538335495,0.62636,31.6
0.7956215,322.6153819894859,0.62656,31.8
0.7956438,322.5970761930771,0.62676,32.0
0.7961422,322.5800931931454,0.627,32.2
0.7967503,322.630786167816,0.62728,32.4
0.7975204,322.7124155117089,0.6276801,32.6
0.7977589,322.889030176828,0.6282,32.8
0.7986578,323.127560251246,0.62872,33.0
0.7997854,323.38418276780226,0.62936,33.2
0.8010115,323.7133884071823,0.63012,33.4
0.8023655,324.12908786782276,0.63108,33.6
0.8038494,324.57563835597733,0.6321601,33.8
0.8060209,325.0447190550966,0.6334401,34.0
0.8084666,325.55314228169595,0.63492,34.2
0.8111231,326.0458199631324,0.63656,34.4
0.8145938,326.52369085819623,0.6385201,34.6
0.8190406,326.9078138868027,0.64072,34.8
0.824054,327.16584454154435,0.64316,35.0
0.8304731,327.32347067658907,0.64588,35.2
0.8374695,327.4454666484604,0.6488001,35.4
0.8456345,327.5300402812863,0.652,35.6
0.8539253,327.64887860995424,0.65536,35.8
0.8626765,327.79843995357413,0.65892,36.0
0.8713125,327.93558407865095,0.66252,36.2
0.8804583,328.1532481054141,0.66636,36.4
0.8893726,328.38529221000886,0.6704,36.6
0.8991241,328.589685601147,0.67448,36.8
0.9093297,328.8382006554243,0.6786401,37.0
0.9194577,329.05723014951866,0.68284,37.2
0.9294356,329.32072267358507,0.68712,37.4
0.9392406,329.57495562231173,0.69148,37.6
0.949725,329.820014337407,0.6958401,37.8
0.9593721,330.0232556154844,0.70004,38.0
0.9684055,330.2314467126374,0.70412,38.2
0.9769332,330.4660937393323,0.70804,38.4
0.9850121,330.6765890626067,0.71184,38.6
0.9926503,330.910553355636,0.7156,38.8
1.000066,331.1516010104458,0.7192801,38.998
1.003917,331.30615484399533,0.72116,39.1
1.011478,331.54267938827064,0.7248401,39.3
1.019307,331.8283180856148,0.7286,39.5
1.027355,332.14958694613233,0.73256,39.7
1.035979,332.4711118317744,0.73676,39.9
1.045587,332.77177066976174,0.74128,40.1
1.055819,333.1404041783301,0.74616,40.3
1.066014,333.47699187546937,0.75148,40.5
1.077453,333.8192974670581,0.7572,40.7
1.089779,334.1476496893562,0.76332,40.9
1.102512,334.49797740151564,0.7698,41.1
1.116555,334.89579777428827,0.7767601,41.3
1.131201,335.3032617600874,0.78416,41.5
1.147577,335.7618880999522,0.79212,41.7
1.164865,336.22298934935486,0.80068,41.9
1.183271,336.73072984228855,0.81,42.1
1.20244,337.2671451491773,0.81988,42.3
1.223163,337.8716204683553,0.8306,42.5
1.244066,338.43470505905645,0.84192,42.7
1.267355,339.08432614187205,0.854,42.9
1.291442,339.75186898340957,0.86644,43.1
1.314558,340.4461664504677,0.8792,43.3
1.33933,341.14985150542776,0.89216,43.5
1.363984,341.83424933433463,0.9052,43.7
1.387821,342.5957107257459,0.91856,43.9
1.412443,343.3190243735919,0.93224,44.1
1.438212,344.10958728749915,0.9464,44.3
1.465339,344.9212296033317,0.9608,44.5
1.492469,345.7146514644637,0.97544,44.7
1.519547,346.51541271250085,0.99048,44.9
1.546677,347.34442206595213,1.00576,45.1
1.575665,348.1703591179081,1.02128,45.3
1.603852,348.9363009489998,1.03676,45.5
1.631437,349.81084010377555,1.05224,45.7
1.659762,350.5801529323411,1.0676,45.9
1.687329,351.37451355226324,1.08272,46.1
1.71371,352.1928978630436,1.09768,46.3
1.740704,352.96605106847824,1.11256,46.5
1.769134,353.75533385676243,1.12748,46.7
1.795646,354.5540042329487,1.14232,46.9
1.821534,355.2403222502902,1.15676,47.1
1.846123,355.9398682324026,1.17072,47.3
1.871265,356.6767085409982,1.18452,47.5
1.895812,357.3660988598348,1.198,47.7
1.919991,358.0537823445074,1.21132,47.9
1.942589,358.6981975831228,1.22432,48.1
1.964933,359.3501655629139,1.23692,48.3
1.987194,359.94516795248177,1.24908,48.5
2.007944,360.5321055506247,1.26104,48.7
2.027487,361.12958284973035,1.27284,48.9
2.048167,361.6961664504677,1.28432,49.1
2.067743,362.20817402881136,1.29536,49.3
2.086489,362.6524629616987,1.3056,49.5
2.103221,363.11672185430467,1.31532,49.7
2.119001,363.6158001638561,1.3246,49.9
2.13468,364.1377927220591,1.3338,50.1
2.150073,364.63849252406635,1.34304,50.3
2.166048,365.0996364443231,1.35224,50.5
2.182857,365.5839079675019,1.36156,50.7
2.198978,365.9958950638356,1.3706,50.9
2.214225,366.3906858059671,1.37944,51.1
2.229363,366.81022564347654,1.38824,51.3
2.243716,367.19767699870283,1.39688,51.5
2.258198,367.62873796681913,1.40552,51.7
2.273263,368.0515634600942,1.41408,51.9
2.288517,368.4680309961084,1.42272,52.1
2.303404,368.8407182358162,1.4312,52.3
2.31831,369.2189100157028,1.43964,52.5
2.332396,369.6390472451697,1.44828,52.7
2.34737,370.083805557452,1.45696,52.9
2.362669,370.4606318700075,1.46572,53.1
2.378083,370.88588960196626,1.4746,53.3
2.394395,371.2879343892947,1.48364,53.5
2.410394,371.73226599303615,1.493,53.7
2.426784,372.1712210691609,1.50256,53.9
2.443689,372.60445825083633,1.5124,54.1
2.461829,373.05514781183854,1.52264,54.3
2.480323,373.4690124257527,1.53312,54.5
2.499904,373.910741107394,1.54388,54.7
2.519334,374.3666365125964,1.55488,54.9
2.538947,374.77132689287913,1.56596,55.1
2.558388,375.22901447395367,1.5772,55.3
2.578174,375.7128166177375,1.58868,55.5
2.599799,376.1891086911995,1.60032,55.7
2.620821,376.64265719942654,1.61212,55.9
2.641596,377.14293029289274,1.62416,56.1
2.662678,377.66513620536625,1.63652,56.3
2.685465,378.1829896907217,1.6492,56.5
2.708456,378.6252730934662,1.66208,56.7
2.731554,379.153111558681,1.67516,56.9
2.754863,379.65735304157846,1.68832,57.1
2.777791,380.11115757493,1.70132,57.3
2.801407,380.6389960401448,1.71444,57.5
2.824374,381.17314979176626,1.7276,57.7
2.847681,381.6568239229876,1.74072,57.9
2.871312,382.14877619990443,1.754,58.1
2.894861,382.6407284768212,1.76728,58.3
2.918889,383.1887502560251,1.78072,58.5
2.942131,383.6583430053936,1.79416,58.7
2.965874,384.17308151839967,1.80768,58.9
2.9891,384.65914521745066,1.82108,59.1
3.013767,385.0960520925787,1.83416,59.3
3.036666,385.5526302314467,1.847,59.5
3.059067,386.02559397828907,1.8598,59.7
3.081088,386.5093107803646,1.87252,59.9
3.103855,386.95534921827,1.885,60.1
3.126469,387.3893544753192,1.8974,60.3
3.148689,387.8340274458934,1.90964,60.5
3.170582,388.30101727316173,1.92184,60.7
3.192075,388.657233563187,1.93384,60.9
3.213535,389.02701918481597,1.94564,61.1
3.234348,389.4840240322251,1.95724,61.3
3.254737,389.82918857103846,1.96844,61.5
3.274406,390.23097733324227,1.97952,61.7
3.29409,390.6428790878678,1.99052,61.9
3.314965,391.03852324708134,2.00148,62.1
3.334658,391.37540964019934,2.0122,62.3
3.353795,391.7286816412917,2.0228,62.5
3.372462,392.0554123711341,2.03328,62.7
3.390949,392.4175599098791,2.04368,62.9
3.410398,392.81183860176145,2.05412,63.1
3.429803,393.11838601761457,2.06432,63.3
3.44884,393.43607052638765,2.07448,63.5
3.467029,393.7732129446303,2.0846,63.7
3.485183,394.06474021984025,2.0944,63.9
3.502299,394.3448743770055,2.10396,64.1
3.520002,394.6753601420086,2.11356,64.3
3.537669,394.9986345326688,2.12316,64.5
3.555257,395.3721751894586,2.13296,64.7
3.573443,395.7165716528982,2.14284,64.9
3.591955,396.01838260394624,2.1528,65.1
3.610475,396.3201935549942,2.16272,65.3
3.628816,396.5357667099065,2.17244,65.5
3.646969,396.8292995152591,2.18208,65.7
3.664335,397.0776865569741,2.19152,65.9
3.68177,397.36405065883804,2.20096,66.1
3.698819,397.67243292141734,2.21048,66.3
3.716899,397.9673738649553,2.22004,66.5
3.735831,398.254506042193,2.22956,66.7
3.753586,398.5685635283676,2.23908,66.9
3.771887,398.845326688059,2.24868,67.1
3.789316,399.1333976240869,2.2584,67.3
3.807844,399.41916433399336,2.26832,67.5
3.826466,399.723834232266,2.27832,67.7
3.845954,400.0403239571243,2.28844,67.9
3.865835,400.2771045265242,2.29868,68.1
3.885324,400.5570680002731,2.30912,68.3
3.905132,400.8872123984433,2.3198,68.5
3.926088,401.1906875128013,2.3306,68.7
3.947147,401.4426162354066,2.3416,68.9
3.968125,401.70657813886805,2.35276,69.1
3.989353,401.9377688263808,2.36376,69.3
4.010889,402.18799071482215,2.3746,69.5
4.031603,402.4462773946883,2.38544,69.7
4.053275,402.6866423158326,2.3962,69.9
4.074177,402.98606369905093,2.40708,70.1
4.094678,403.2930804942992,2.418,70.3
4.1161,403.58669864136004,2.42908,70.5
4.137906,403.8227538062402,2.44016,70.7
4.16008,404.1080511367515,2.45128,70.9
4.181904,404.359211783983,2.46228,71.1
4.203073,404.63652966477775,2.47328,71.3
4.224498,404.916194442548,2.4844,71.5
4.246583,405.1436727657541,2.49544,71.7
4.268432,405.44706253840377,2.50648,71.9
4.290569,405.6756929746706,2.51744,72.1
4.311889,405.90786509182766,2.52836,72.3
4.332869,406.1285587492319,2.53924,72.5
4.354855,406.39375810746225,2.54992,72.7
4.376111,406.63651259643615,2.5606,72.9
4.397032,406.86215607291604,2.57116,73.1
4.417735,407.128891581894,2.5818,73.3
4.438853,407.37907079948116,2.59236,73.5
4.460375,407.5726257936779,2.60272,73.7
4.480428,407.70396668259707,2.61268,73.9
4.49967,407.8712364306684,2.6224,74.1
4.518067,408.0834812589609,2.63196,74.3
4.537507,408.4070116747457,2.6416,74.5
4.557337,408.70250733938684,2.6514,74.7
4.577685,408.92597460230763,2.66124,74.9
4.597351,409.1432119205298,2.67116,75.1
4.616889,409.3321584624838,2.68096,75.3
4.636515,409.53638117020546,2.69064,75.5
4.6565,409.71350788557385,2.70028,75.7
4.676215,409.8985287089506,2.70988,75.9
4.695953,410.11713149450395,2.71956,76.1
4.71557,410.3644517648665,2.7292,76.3
4.735522,410.54644295760227,2.73876,76.5
4.754679,410.7128592885915,2.74832,76.7
4.774918,410.83728749914656,2.75768,76.9
4.793591,410.95949682528845,2.76676,77.1
4.811319,411.1767341435106,2.77584,77.3
4.83041,411.3447719669557,2.7848,77.5
4.848506,411.54293541339524,2.79372,77.7
4.867265,411.7453659452447,2.80264,77.9
4.885981,411.94032907762687,2.81156,78.1
4.90433,412.19780501126513,2.8206,78.3
4.922408,412.3519748071277,2.82956,78.5
4.940756,412.4896309824537,2.83848,78.7
4.959488,412.68877585853755,2.84756,78.9
4.979458,412.8589045538336,2.85672,79.1
4.998828,413.09555711067117,2.86604,79.3
5.018161,413.2486174643272,2.87536,79.5
5.037684,413.4219038028265,2.88476,79.7
5.056562,413.4873608930156,2.89404,79.9
5.076548,413.6268092442138,2.90328,80.1
5.095935,413.8118727384447,2.91252,80.3
5.11569,413.94142145149175,2.92168,80.5
5.134974,414.1201269884618,2.93092,80.7
5.154435,414.2760036184884,2.94032,80.9
5.174429,414.457098723288,2.94972,81.1
5.194354,414.657566395849,2.95924,81.3
5.213819,414.7963746842357,2.96872,81.5
5.23379,414.975634942309,2.97832,81.7
5.254324,415.0982709769919,2.98796,81.9
5.276037,415.2797501194784,2.99768,82.1
5.296934,415.42483102341777,3.00744,82.3
5.317629,415.5856148016659,3.01728,82.5
5.337656,415.6583686079061,3.02696,82.7
5.357788,415.75497542158803,3.0366,82.9
5.378886,415.94912780774223,3.04628,83.1
5.400138,416.09988393527686,3.05588,83.3
5.420832,416.231608861883,3.06548,83.5
5.441009,416.37809790400763,3.07512,83.7
5.46124,416.5482265993036,3.08488,83.9
5.482498,416.72919369154096,3.09468,84.1
5.503614,416.88024851505435,3.10452,84.3
5.524603,416.99656926333034,3.11436,84.5
5.54546,417.0848552604629,3.12408,84.7
5.566591,417.2557093602785,3.13388,84.9
5.588162,417.3886717416535,3.14364,85.1
5.608979,417.5105397009626,3.15328,85.3
5.629366,417.55440533897723,3.16276,85.5
5.649069,417.6796016249062,3.17212,85.7
5.6691,417.8405560865706,3.18152,85.9
5.689892,417.9532924831023,3.1908,86.1
5.708753,418.09995220864334,3.20012,86.3
5.728522,418.2187478664573,3.20936,86.5
5.748602,418.37769679797907,3.21868,86.7
5.767988,418.5201747798184,3.228,86.9
5.787993,418.62062197036937,3.2372,87.1
5.808649,418.7586195125281,3.24648,87.3
5.828431,418.8121287635693,3.25564,87.5
5.847685,418.9526865569741,3.26492,87.7
5.867526,419.10898989554175,3.2742,87.9
5.887738,419.26328770396674,3.28348,88.1
5.90785,419.3221734826244,3.29264,88.3
5.927368,419.4316668942446,3.30184,88.5
5.946489,419.5265668737626,3.31104,88.7
5.966103,419.6622601898,3.32016,88.9
5.986352,419.80072711135386,3.32932,89.1
6.006275,419.87932682460576,3.33844,89.3
6.026096,419.9744828292483,3.3476,89.5
6.045435,420.09460128353925,3.35688,89.7
6.065442,420.2078070594661,3.36604,89.9
6.084903,420.30172560933977,3.37516,90.1
6.105262,420.41889977469793,3.38432,90.3
6.125152,420.47859629958356,3.39344,90.5
6.145122,420.5763552263262,3.40256,90.7
6.164536,420.7356881955349,3.41172,90.9
6.184527,420.8170615143033,3.42088,91.1
6.204747,420.8643408206459,3.42996,91.3
6.224977,420.95091998361437,3.43912,91.5
6.244766,421.0792312418925,3.44832,91.7
6.26481,421.22695773878615,3.45756,91.9
6.285443,421.303423909333,3.46676,92.1
6.30606,421.29800471086224,3.47568,92.3
6.326022,421.3762203864273,3.4846,92.5
6.345697,421.39631835870824,3.49336,92.7
6.364603,421.485969823172,3.502,92.9
6.383594,421.63877415170344,3.51072,93.1
6.403561,421.742464327166,3.51952,93.3
6.423284,421.84380760565307,3.5284,93.5
6.443074,421.9603843790538,3.53736,93.7
6.463114,422.09663241619444,3.5464,93.9
6.483243,422.14071140847955,3.55532,94.1
6.503345,422.1567983204752,3.56412,94.3
6.523946,422.25088755376527,3.573,94.5
6.543896,422.3157045811429,3.58192,94.7
6.563234,422.42728886461396,3.5908,94.9
6.583541,422.529058851642,3.59976,95.1
6.603426,422.55470403495593,3.60856,95.3
6.623975,422.65698607223317,3.61748,95.5
6.644716,422.7258568307504,3.62644,95.7
6.664985,422.85015702874307,3.63548,95.9
6.686029,422.9412166313921,3.64456,96.1
6.706609,422.97633474431626,3.65364,96.3
6.727988,423.0304413873148,3.66276,96.5
6.749133,423.0604816686011,3.6718,96.7
6.770086,423.1415989622448,3.6808,96.9
6.790435,423.1016163719533,3.68948,97.1
6.811093,423.12380521608526,3.69804,97.3
6.831171,423.21315798457016,3.70664,97.5
6.851128,423.3170615143033,3.7152,97.7
6.870484,423.39847750392573,3.7238,97.9
6.890856,423.51240868437225,3.73244,98.1
6.910823,423.5573410937393,3.74096,98.3
6.93145,423.60146275687856,3.74952,98.5
6.951988,423.58264491022055,3.75788,98.7
6.971635,423.6420427391275,3.7662,98.9
6.990961,423.7489758995016,3.77456,99.1
7.010946,423.84157165289815,3.78292,99.3
7.030806,423.8824503311258,3.79124,99.5
7.051056,424.014601966273,3.79976,99.7
7.071152,424.0649535741108,3.80828,99.9
7.091777,424.14193179490684,3.81676,100.1
7.112279,424.07225029016183,3.82492,100.3
7.132071,424.07587731276027,3.83292,100.5
7.151736,424.110355362873,3.84088,100.7
7.170749,424.1226445688537,3.84868,100.9
7.189302,424.149740561207,3.85652,101.1
7.208014,424.3139380077832,3.86444,101.3
7.227539,424.37329316583595,3.87228,101.5
7.246847,424.47736737898543,3.88024,101.7
7.266867,424.5283163787807,3.88816,101.9
7.285877,424.5122294667851,3.89596,102.1
7.304328,424.53224209735777,3.90372,102.3
7.323462,424.55899672287836,3.91136,102.5
7.342043,424.53561309483166,3.9188,102.7
7.36102,424.5672321977196,3.9262,102.9
7.379684,424.70160271728,3.93384,103.1
7.398532,424.8486891513621,3.94168,103.3
7.418398,424.97887792722065,3.94972,103.5
7.438704,425.0334112787602,3.95772,103.7
7.459396,425.068828087663,3.96576,103.9
7.480106,425.0652864067727,3.97384,104.1
7.500578,425.0392571857718,3.9818,104.3
7.520954,425.0022615552673,3.98964,104.5
7.541464,425.03780637673236,3.99748,104.7
7.562145,425.0497968867345,4.00524,104.9
7.582564,425.1099201201612,4.01312,105.1
7.602362,425.19214685601145,4.02104,105.3
7.622826,425.1811377756537,4.02892,105.5
7.644372,425.1923175394279,4.03692,105.7
7.665119,425.31768450877314,4.04504,105.9
7.686672,425.341153478528,4.05308,106.1
7.70808,425.34985833276437,4.06112,106.3
7.729295,425.3115825766369,4.06908,106.5
7.750576,425.30441387314806,4.07708,106.7
7.772064,425.27940875264557,4.08488,106.9
7.792853,425.20115040622653,4.09244,107.1
7.812879,425.2093005393596,4.09992,107.3
7.832296,425.2122021574384,4.10732,107.5
7.852484,425.2448880316789,4.1146,107.7
7.872093,425.25615313716116,4.12184,107.9
7.890884,425.34554857650033,4.12908,108.1
7.910072,425.3740953778931,4.13628,108.3
7.929055,425.413395234519,4.14336,108.5
7.949013,425.4679712569127,4.15052,108.7
7.968212,425.50586297535335,4.1576,108.9
7.987872,425.5172134225439,4.16476,109.1
8.006999,425.62905373113944,4.172,109.3
8.026611,425.7095736328258,4.17936,109.5
8.046891,425.690841127876,4.1866,109.7
8.067543,425.70526387656173,4.19392,109.9
8.088428,425.7064586604765,4.20128,110.1
8.108045,425.708378848911,4.2086,110.3
8.128603,425.6835444118249,4.21588,110.5
8.148146,425.59619717348266,4.22296,110.7
8.167925,425.62248241960816,4.23,110.9
8.187841,425.66681743701776,4.23708,111.1
8.20747,425.6983938690517,4.2442,111.3
8.227032,425.6838004369496,4.25132,111.5
8.247224,425.7124752509046,4.25848,111.7
8.266927,425.72007066293435,4.2656,111.9
8.287329,425.6897316856694,4.2726,112.1
8.306655,425.70517853485364,4.2796,112.3
8.326373,425.7032583464191,4.28656,112.5
8.345915,425.67023110534575,4.2934,112.7
8.365437,425.6589233290093,4.30016,112.9
8.384844,425.6757783163788,4.30704,113.1
8.404189,425.7714463712706,4.314,113.3
8.424044,425.79269645661225,4.32088,113.5
8.443281,425.80810063494226,4.32788,113.7
8.463665,425.7631682255752,4.33476,113.9
8.483886,425.7679046903803,4.34172,114.1
8.503947,425.74324093671066,4.34872,114.3
8.523258,425.7064586604765,4.35556,114.5
8.541936,425.6691216631392,4.36236,114.7
8.56127,425.6829470198676,4.36916,114.9
8.580507,425.7330852734348,4.37612,115.1
8.600409,425.7311224141462,4.38308,115.3
8.619272,425.7345360824743,4.39004,115.5
8.639103,425.7242524066362,4.39712,115.7
8.658408,425.75740766027167,4.40424,115.9
8.677857,425.7013381579846,4.41132,116.1
8.696973,425.6445005803236,4.41836,116.3
8.715454,425.5716614323752,4.42536,116.5
8.73363,425.5778060353656,4.43248,116.7
8.752375,425.6329367788626,4.4398,116.9
8.771082,425.650645183314,4.4472,117.1
8.790718,425.6342169044856,4.45464,117.3
8.809735,425.6316566532396,4.46224,117.5
8.828408,425.5987147538745,4.46996,117.7
8.847098,425.54610159076947,4.47776,117.9
8.865327,425.44629446303,4.4856,118.1
8.884373,425.4053731139482,4.49352,118.3
8.903157,425.3690602171093,4.50152,118.5
8.922188,425.30769952891376,4.5096,118.7
8.940957,425.2686556974124,4.5178,118.9
8.959309,425.258628046699,4.52628,119.1
8.978686,425.20426537857577,4.53492,119.3
8.998284,425.17802280330443,4.54368,119.5
9.017732,425.0783863589814,4.55252,119.7
9.037218,424.98259029152723,4.56152,119.9
9.056725,424.9265207892401,4.57072,120.1
9.07594,424.9007049225097,4.58028,120.3
9.096102,424.819587628866,4.59004,120.5
9.114976,424.6837236294122,4.59992,120.7
9.133918,424.5845565644842,4.61012,120.9
9.151667,424.4013705878337,4.62036,121.1
9.16952,424.32942752782145,4.63072,121.3
9.188167,424.26691472656523,4.64132,121.5
9.206811,424.12861848842766,4.65208,121.7
9.224925,423.986396531713,4.6632,121.9
9.243076,423.8606028538267,4.67456,122.1
9.261215,423.6958933570014,4.68616,122.3
9.279173,423.48552604628935,4.698,122.5
9.297802,423.328881340889,4.71028,122.7
9.317277,423.1569177988667,4.72292,122.9
9.337096,422.88924353109854,4.736,123.1
9.356716,422.5849149996586,4.74948,123.3
9.375302,422.2763193828087,4.76312,123.5
9.394453,422.00442070048473,4.7768,123.7
9.412715,421.69727589267427,4.79052,123.9
9.430728,421.37686044923873,4.80436,124.1
9.447978,421.12412098040556,4.81852,124.3
9.465163,420.69139584897925,4.833,124.5
9.482123,420.2771471973783,4.84804,124.7
9.498755,419.8924267768144,4.86368,124.9
9.514711,419.3322864750461,4.87984,125.1
9.530059,418.78114972349283,4.89624,125.3
9.544975,418.22544719055094,4.91316,125.5
9.558731,417.5793677886257,4.93056,125.7
9.571749,416.9107581757357,4.94868,125.9
9.584303,416.1196832115792,4.967441,126.1
9.59584,415.24744828292484,4.98668,126.3
9.606657,414.3850703215676,5.00664,126.5
9.616241,413.36387144125075,5.027481,126.7
9.624972,412.3142964429576,5.04936,126.9
9.632436,411.02849559636786,5.07208,127.1
9.639306,409.72562640813817,5.09584,127.3
9.644359,408.21563289410796,5.12104,127.5
9.648472,406.54703181538883,5.14752,127.7
9.651034,404.6654178330034,5.17508,127.9
9.651761,402.48237693725673,5.20416,128.1
9.648097,400.12148392162214,5.2344,128.3
9.645172,397.3002577319587,5.26688,128.5
9.640626,393.8414009694818,5.30136,128.7
9.405606,370.95569911927356,5.30912,128.742
8.77209,337.64781183860174,5.31112,128.746
7.736373,296.617225370383,5.31424,128.75
6.459925,251.99635590905987,5.31844,128.754
5.077968,207.40454529937873,5.32288,128.758
3.696054,165.11077353724312,5.32716,128.762
2.390685,126.70721820167954,5.33156,128.766
1.779877,109.24566464122346,5.33368,128.768