File: Tensile Al7075/formatted-CSV/Group2-160C-2h_tensile-test.csv
Strain (percent),Stress (MPa),Extension (mm),Time (s)
-3.021269e-05,-2.1583472963335306,0.0,0.0
0.0002701775,-2.1806593113877937,0.0,0.2
0.0002617006,-2.1805579185248196,0.0,0.4
2.613651e-05,-2.1766723377929007,0.0,0.6
0.0003396829,-2.186380274791844,0.0,0.8
0.0001693124,-2.1706020845685217,0.0,1.0
-9.611676e-05,-2.15964864795195,0.00012,1.2
-0.0002043072,-2.157115115269937,0.0002,1.4
0.0001556416,-2.1715339537201728,0.00032,1.6
0.0001044129,-2.1653833595408107,0.00052,1.8
-0.0002098441,-2.1477276828293768,0.00072,2.0
0.0002398468,-2.1380786052466507,0.0009600001,2.2
5.355159e-05,-2.1060444753778604,0.00128,2.4
0.0003132233,-2.0890100447675266,0.00164,2.6
0.0002597896,-2.0598862337706976,0.00204,2.8
0.0001355764,-2.0119179577071464,0.00248,3.0
0.0003853993,-1.9648798322721452,0.00296,3.2
0.0003545787,-1.8933170932900265,0.0036,3.4
0.0004562277,-1.8161747394289347,0.00432,3.6
0.0008404311,-1.7058515711597455,0.00512,3.8
0.0009669719,-1.5843214841165505,0.00604,4.0
0.0008815171,-1.3721118071129672,0.00716,4.2
0.001349877,-1.1022130281236306,0.0084,4.4
0.002383713,-0.7139836224748451,0.009840001,4.6
0.003180637,-0.0636709801596508,0.0116,4.8
0.004491393,0.9989048711537305,0.01368,5.0
0.00746244,2.7023135617250538,0.0162,5.2
0.01059614,5.001155706785588,0.01928,5.4
0.0150256,7.648420247639179,0.02292,5.6
0.01992021,10.697544230488319,0.02712,5.8
0.0259803,14.105998504884901,0.03184,6.0
0.03201787,17.991712422344236,0.03728,6.2
0.03887424,22.344155732563436,0.04348,6.4
0.04615644,27.137851330566512,0.05044,6.6
0.05482268,32.3943409034276,0.05816,6.8
0.063603,38.25509756914907,0.06660001,7.0
0.0735208,44.52444169480749,0.07568,7.2
0.08340658,51.068835442820436,0.0852,7.4
0.09349247,58.007759131802125,0.09524,7.6
0.1050285,65.25915328366803,0.10588,7.8
0.1164813,72.7099820414336,0.11676,8.0
0.1283172,80.29206300105689,0.12796,8.2
0.1399968,87.9845590699353,0.13944,8.4
0.1523327,95.85015337818679,0.1512,8.6
0.1649813,103.8733362548226,0.16316,8.8
0.1768799,111.80457814554173,0.17512,9.0
0.1893032,119.74217857173545,0.18724,9.2
0.202101,127.93893228159719,0.19968,9.4
0.2149455,136.38835185041975,0.21248,9.6
0.228909,144.8833982075804,0.22548,9.8
0.2417861,153.21290782701345,0.23844,10.0
0.254714,161.4179104477612,0.25096,10.2
0.2665489,169.35099975081417,0.2632,10.4
0.2781924,177.1540827812578,0.27528,10.6
0.2900913,184.81130616348312,0.2872,10.8
0.3024221,192.41847756038462,0.29896,11.0
0.3142602,199.87450485053145,0.3106,11.2
0.3260486,207.19305029257856,0.32208,11.4
0.3372976,214.325264867373,0.33336,11.6
0.3484678,221.33679615738237,0.34436,11.8
0.3594253,228.07280523118433,0.35496,12.0
0.369725,234.5336787564767,0.3652,12.2
0.3788245,240.6890418374449,0.37504,12.4
0.387824,246.51990479382022,0.38416,12.6
0.3960609,251.87765834042227,0.39272,12.8
0.4041663,256.8440612137929,0.40072,13.0
0.4114727,261.4922795349676,0.40824,13.2
0.417959,265.76452796466714,0.4152,13.4
0.4244225,269.84683662860135,0.4218,13.6
0.4311224,273.6055044294933,0.4278,13.8
0.4364928,277.0517017675011,0.43336,14.0
0.4419609,280.1455589066756,0.43844,14.2
0.4463901,283.0539014770706,0.44312,14.4
0.4506848,285.6246831473032,0.44732,14.6
0.4542803,287.9157322197304,0.45108,14.8
0.4574241,289.88167968447914,0.45432,15.0
0.4601285,291.587915345552,0.4572,15.2
0.4626179,293.04844516622416,0.45972,15.4
0.4642977,294.32479227352013,0.46184,15.6
0.4663749,295.3547031680974,0.46356,15.8
0.467255,296.2091098909597,0.465,16.0
0.468269,296.88479021129245,0.46624,16.2
0.4692046,297.4364790898702,0.4672,16.4
0.47007,297.86722690519764,0.468,16.6
0.4707968,298.18871961436344,0.46856,16.8
0.4710511,298.39657498345923,0.46904,17.0
0.47141,298.5742273090506,0.4694,17.2
0.4714825,298.67579202433427,0.46964,17.4
0.4717036,298.73559662825767,0.46984,17.6
0.471575,298.7947567860181,0.46996,17.8
0.4714215,298.8028768076715,0.47008,18.0
0.4717511,298.8133597985891,0.47012,18.2
0.4711929,298.789171585939,0.47016,18.4
0.4716279,298.77787229654837,0.4702,18.6
0.4714129,298.76859227180165,0.47028,18.8
0.4715902,298.7603003978381,0.47032,19.0
0.4717712,298.75454334544895,0.4704,19.2
0.4719855,298.7520514869521,0.47052,19.4
0.4718462,298.75664853624795,0.47072,19.6
0.471856,298.8341109650367,0.471,19.8
0.4722557,298.99887436736867,0.47144,20.0
0.4726764,299.3305493259094,0.47192,20.2
0.4734297,299.77302606140285,0.4726,20.4
0.4743415,300.31363046597755,0.47348,20.6
0.4752156,301.0132412204951,0.47456,20.8
0.4767956,301.8322034043943,0.47584,21.0
0.478025,302.8026104365908,0.47732,21.2
0.480179,303.9277704740546,0.47912,21.4
0.481757,305.29515634263913,0.48128,21.6
0.4844962,306.8645116386977,0.4838,21.8
0.4875146,308.7450485053145,0.48676,22.0
0.4908685,310.8108421622458,0.49008,22.2
0.4944315,313.08801416063034,0.49372,22.4
0.4979752,315.5850711898195,0.4978,22.6
0.5030402,318.3720001031114,0.50232,22.8
0.5078097,321.31913833251707,0.5072,23.0
0.5130327,324.4201703056394,0.51228,23.2
0.51833,327.6577389391557,0.5176,23.4
0.5237826,331.0790606552729,0.52316,23.6
0.5303508,334.65053832736146,0.52912,23.8
0.5362238,338.395586832676,0.53532,24.0
0.5427558,342.2452933948565,0.5418,24.2
0.549458,346.18530834600745,0.54852,24.4
0.5559769,350.39710772562063,0.55564,24.6
0.5634978,354.7123192328513,0.56292,24.8
0.5711644,359.11457393516014,0.57048,25.0
0.5790197,363.7205165880443,0.5784,25.2
0.5871075,368.40744464207455,0.5865601,25.4
0.595139,373.11387793330414,0.59484,25.6
0.6043159,377.96947902972187,0.60344,25.8
0.6135622,382.9012106995249,0.61216,26.0
0.6228285,387.7837066824771,0.6209601,26.2
0.6326867,392.6421863050894,0.62996,26.4
0.6435709,397.53877417747185,0.6392,26.6
0.6540533,402.2814683061377,0.64832,26.8
0.6646787,406.78507290834256,0.65736,27.0
0.6756147,411.12601929901444,0.66636,27.2
0.6866355,415.1886079103618,0.67512,27.4
0.6975736,418.9443542219816,0.68376,27.6
0.7094704,422.49563924763066,0.69232,27.8
0.7213556,425.7811117125942,0.70056,28.0
0.7340609,428.83703245430877,0.70864,28.2
0.7462862,431.58602497014067,0.71648,28.4
0.7578227,434.06284638981265,0.72396,28.6
0.7702678,436.27931155964563,0.73116,28.8
0.7819063,438.3411096503665,0.73808,29.0
0.7930217,440.1365366603941,0.74456,29.2
0.8042724,441.7137112365633,0.7506,29.4
0.8150482,443.0975519638423,0.75624,29.6
0.8248199,444.2390809338455,0.7613601,29.8
0.8342433,445.2491428866033,0.76608,30.0
0.8430829,446.0890710523376,0.77032,30.2
0.8508545,446.729220907552,0.774,30.4
0.8573797,447.19966660651835,0.77712,30.6
0.8634749,447.48880811830315,0.77968,30.8
0.8677479,447.64906039749434,0.7816801,31.0
0.8716341,447.63144553570663,0.7832,31.2
0.8747397,447.5077118724169,0.78432,31.4
0.8773001,447.2821557153782,0.78504,31.6
0.878603,447.02394761941594,0.78552,31.8
0.8798892,446.70258379948274,0.78576,32.0
0.8810875,446.36489401008777,0.7858,32.2
0.8815823,446.01517455898403,0.7858,32.4
0.8822772,445.7109959700634,0.7858,32.6
0.8827908,445.43903968929106,0.7858,32.8
0.8830585,445.19114273193617,0.7858,33.0
0.8834573,444.97675697505565,0.7858,33.2
0.8840169,444.75893417197267,0.7858,33.4
0.884181,444.5617336461045,0.7858,33.6
0.8842679,444.3933183821824,0.7858,33.8
0.8851068,444.24380687237385,0.7858,34.0
0.8851103,444.09085831636287,0.7858,34.2
0.8853214,443.9396282834532,0.7858,34.4
0.8856022,443.8171835124894,0.7858,34.6
0.8858628,443.6857164952439,0.7858,34.8
0.8860759,443.56971618590984,0.7858,35.0
0.886115,443.4644566459585,0.7858,35.2
0.8864745,443.34974522895027,0.7858,35.4
0.8862299,443.2526486737298,0.7858,35.6
0.8868068,443.1555521185093,0.7858,35.8
0.8869966,443.0511518401087,0.7858,36.0
0.8867954,442.9746775621031,0.7858,36.2
0.8871029,442.88445509928766,0.7858,36.4
0.8867138,442.80583266740564,0.7858,36.6
0.8869777,442.70615832753333,0.7858,36.8
0.8872154,442.63956555736,0.7858,37.0
0.8875804,442.56824684865825,0.7858,37.2
0.887638,442.4801725397194,0.7858,37.4
0.8875728,442.4264686928054,0.78592,37.6
0.8873471,442.3843648768249,0.78612,37.8
0.8875686,442.3517129379012,0.78648,38.0
0.8878366,442.4110019848942,0.78696,38.2
0.888548,442.68252863489124,0.7876,38.4
0.8898457,443.2715524278436,0.78856,38.6
0.8912928,444.1110509628026,0.78984,38.8
0.8931748,445.1666537777434,0.79144,39.0
0.8957354,446.3984052105621,0.79344,39.2
0.8986907,447.82864606157466,0.7958,39.4
0.9020803,449.4754208233444,0.79868,39.6
0.9063477,451.21800324800864,0.80192,39.8
0.9113953,453.0018302271028,0.80556,40.0
0.9173739,454.73882745168805,0.80964,40.2
0.9248939,456.241246272953,0.81424,40.4
0.9346462,457.419723489633,0.81928,40.6
0.9469354,458.201221869925,0.82468,40.8
0.9611234,458.73353440053614,0.83028,41.0
0.975176,459.2976396085205,0.83624,41.2
0.9902628,459.902130109384,0.84236,41.4
1.000025,460.33820534632537,0.8466,41.534
1.007783,460.63035427353736,0.84988,41.636
1.02404,461.3611562223425,0.85648,41.836
1.04041,462.13363235635296,0.86356,42.036
1.058567,462.9967605839542,0.871,42.236
1.076899,463.72842179430995,0.87868,42.436
1.096026,464.5451498981775,0.88668,42.636
1.11586,465.29141855489394,0.8950401,42.836
1.137549,466.0570205964994,0.90372,43.036
1.159388,466.77579288359584,0.91252,43.236
1.181304,467.49843184767013,0.9214,43.436
1.202848,468.2408338274088,0.93048,43.636
1.22479,468.9329690064359,0.93964,43.836
1.247653,469.57397812320085,0.94896,44.036
1.271334,470.2738466561837,0.95848,44.236
1.29539,470.989611527853,0.96812,44.436
1.318785,471.683035599206,0.97804,44.636
1.343286,472.36185222419857,0.98816,44.836
1.369297,473.0539874032256,0.99864,45.036
1.395198,473.7134706433291,1.00924,45.236
1.421371,474.33256859055325,1.01988,45.436
1.447822,474.8442588439495,1.03032,45.636
1.474274,475.3224378968714,1.04052,45.836
1.497741,475.72156488713597,1.05028,46.036
1.520096,476.1924402168776,1.05972,46.236
1.542636,476.67362668522674,1.06896,46.436
1.565289,477.142783491867,1.078,46.636
1.587522,477.6153773447099,1.087,46.836
1.608446,478.0682081818885,1.09584,47.036
1.629564,478.56056505039567,1.10468,47.236
1.650006,479.0215588723052,1.11344,47.436
1.671427,479.4408785090094,1.12212,47.636
1.691594,479.8773833767261,1.13092,47.836
1.712354,480.2773696285413,1.13964,48.036
1.732066,480.6915336959417,1.14816,48.236
1.751875,481.0532828087542,1.15664,48.436
1.771632,481.4429579219618,1.16504,48.636
1.790787,481.75701801871475,1.17332,48.836
1.809133,482.02854466871173,1.18136,49.036
1.827086,482.3842789506698,1.18928,49.236
1.84439,482.73743544797605,1.19712,49.436
1.862239,483.0622363141117,1.20484,49.636
1.880354,483.3393481641877,1.2124,49.836
1.897054,483.7058232155286,1.22012,50.036
1.913793,484.0168758968542,1.22768,50.236
1.929237,484.352847163148,1.23516,50.436
1.945646,484.6999888295999,1.24268,50.636
1.961871,485.08536763505447,1.25028,50.836
1.978778,485.4879316715215,1.25808,51.036
1.996366,485.9540810627347,1.2662,51.236
2.014156,486.3764081148661,1.27464,51.436
2.031542,486.8176389211112,1.28328,51.636
2.050142,487.16091391058524,1.29204,51.836
2.068892,487.51492966944204,1.301,52.036
2.087744,487.6678782254531,1.30968,52.236
2.105169,487.82598235076784,1.31816,52.436
2.12209,488.1366054013181,1.32672,52.636
2.140255,488.5060878680862,1.3354,52.836
2.158094,488.8665480885727,1.34428,53.036
2.176399,489.3133640948968,1.35348,53.236
2.196041,489.71592813136397,1.36296,53.436
2.215725,490.16360339923875,1.3728,53.636
2.235618,490.5124635887918,1.38276,53.836
2.255525,490.79043470041853,1.3928,54.036
2.276858,491.1397245207469,1.40316,54.236
2.298052,491.43058455563295,1.41352,54.436
2.319239,491.81037816100843,1.42412,54.636
2.341022,492.19919401266554,1.43492,54.836
2.362469,492.4582613701785,1.44572,55.036
2.384862,492.7121731583877,1.45648,55.236
2.406883,493.0485740554568,1.46724,55.436
2.429366,493.31107845917217,1.4778,55.636
2.451405,493.65950901795,1.48848,55.836
2.474065,494.0277025923921,1.4994,56.036
2.497756,494.5084594299659,1.51068,56.236
2.522161,494.8861048814649,1.522,56.436
2.546433,495.1885649472843,1.53344,56.636
2.571315,495.42572113525637,1.54476,56.836
2.595903,495.7161515393671,1.556,57.036
2.620422,495.98810782013936,1.56712,57.236
2.64407,496.2093676694249,1.57796,57.436
2.666949,496.446523857397,1.5886,57.636
2.690488,496.79237663152287,1.59916,57.836
2.713379,497.05788845066553,1.60948,58.036
2.735675,497.3564818395072,1.61972,58.236
2.756969,497.60351953531136,1.62968,58.436
2.778369,497.8857869546911,1.63956,58.636
2.800055,498.1727803125994,1.64928,58.836
2.821768,498.4443069625964,1.65888,59.036
2.842602,498.75063370539357,1.6684,59.236
2.86222,498.9555675852173,1.67772,59.436
2.881969,499.20475343489807,1.68696,59.636
2.901552,499.4891690081544,1.696,59.836
2.921328,499.69796956495594,1.7048,60.036
2.939749,499.808384674211,1.71324,60.236
2.957289,499.96734806107634,1.72148,60.436
2.974862,500.21911169540897,1.72964,60.636
2.991735,500.46142345268476,1.73764,60.836
3.009166,500.72521674872615,1.74552,61.036
3.025748,500.9834248446885,1.75332,61.236
3.041694,501.2141365710309,1.76108,61.436
3.057821,501.4607446360598,1.76884,61.636
3.074185,501.747737993968,1.77656,61.836
3.089905,502.00422756682906,1.78424,62.036
3.106645,502.304539478772,1.79192,62.236
3.124235,502.6130143754457,1.79984,62.436
3.140584,502.9300818876258,1.80784,62.636
3.157305,503.2256678610402,1.816,62.836
3.173789,503.52512051143253,1.82428,63.036
3.190891,503.8439065467138,1.83268,63.236
3.208093,504.0806331039105,1.84108,63.436
3.226245,504.2047963979756,1.8494,63.636
3.24389,504.4290636626883,1.85784,63.836
3.262319,504.68770138942597,1.8664,64.036
3.279837,504.9532132085686,1.87504,64.236
3.298262,505.2492288127583,1.88392,64.436
3.317018,505.4494367540536,1.8928,64.636
3.33581,505.666400295586,1.90192,64.836
3.35505,505.9817492846647,1.91132,65.036
3.374894,506.25972039629147,1.92084,65.236
3.395646,506.54284707722184,1.93052,65.436
3.417306,506.85046271234506,1.94064,65.636
3.439616,507.10222634667764,1.95096,65.836
3.46179,507.40468641249714,1.96148,66.036
3.483843,507.56665721478964,1.972,66.236
3.506392,507.5963017382861,1.9822,66.436
3.529086,507.74452435576865,1.99252,66.636
3.552472,507.94988786636765,2.00284,66.836
3.574684,508.1677106694507,2.01308,67.036
3.596941,508.3902594110622,2.0234,67.236
3.619114,508.60421553716736,2.03372,67.436
3.642104,508.79754938605765,2.04412,67.636
3.66496,509.08755015939306,2.05456,67.836
3.688627,509.3186915165107,2.06504,68.036
3.711971,509.5034327498948,2.07548,68.236
3.735404,509.72426296840496,2.086,68.436
3.758077,509.9330635252065,2.0964,68.636
3.780691,510.0739824195087,2.10652,68.836
3.801935,510.1083528815337,2.11624,69.036
3.823724,510.2956718995695,2.12592,69.236
3.845761,510.49673910241535,2.13556,69.436
3.866857,510.7532286752765,2.14508,69.636
3.887367,510.99124412479915,2.15456,69.836
3.9081,511.20820766633165,2.164,70.036
3.928494,511.42087490011085,2.17344,70.236
3.949548,511.5794086562009,2.18264,70.436
3.969656,511.80926112099263,2.19176,70.636
3.990009,512.020639462446,2.20084,70.836
4.009885,512.1645657721755,2.20976,71.036
4.029247,512.3587588826163,2.21872,71.236
4.048803,512.5409223313484,2.2276,71.436
4.067492,512.7669081191624,2.23636,71.636
4.086404,512.8309231046838,2.24472,71.836
4.104048,512.8949380902053,2.25284,72.036
4.121915,513.03929403071,2.26096,72.236
4.139019,513.2549686799165,2.26908,72.436
4.157275,513.5286434837901,2.27728,72.636
4.174907,513.8242294572045,2.28552,72.836
4.192427,514.1069265073596,2.29376,73.036
4.209955,514.3934902344926,2.30224,73.236
4.22822,514.6542761151067,2.31084,73.436
4.247008,514.8978767647085,2.31956,73.636
4.266275,515.1161291985668,2.32824,73.836
4.28479,515.2445888003849,2.33672,74.036
4.302742,515.3605891097192,2.3452,74.236
4.320742,515.474870895952,2.3536,74.436
4.338394,515.6029008669949,2.36204,74.636
4.35682,515.7799087464233,2.37036,74.836
4.374891,515.8937609018809,2.37856,75.036
4.392511,516.064753950455,2.3868,75.236
4.409807,516.2941767844715,2.39524,75.436
4.427168,516.5437922649274,2.4038,75.636
4.445581,516.8337930382629,2.41264,75.836
4.464788,517.0816899956178,2.42148,76.036
4.483054,517.2870535062168,2.43036,76.236
4.502185,517.524639324964,2.43952,76.436
4.521601,517.7171139123038,2.4488,76.636
4.540842,517.9667293927599,2.45832,76.836
4.5615,518.243841242836,2.46804,77.036
4.581779,518.429871368546,2.47792,77.236
4.602322,518.6343756175942,2.48804,77.436
4.623609,518.818687220203,2.49848,77.636
4.644633,518.9316801141099,2.50876,77.836
4.666831,519.0313544539823,2.519,78.036
4.688147,519.1421991940127,2.52932,78.236
4.709029,519.2014882410057,2.53952,78.436
4.729494,519.3973998745478,2.54992,78.636
4.751102,519.5980374466184,2.56036,78.836
4.773489,519.8291788037361,2.57108,79.036
4.795886,520.0409867759648,2.58204,79.236
4.818136,520.21369834764,2.59312,79.436
4.840608,520.4491360125108,2.60428,79.636
4.862703,520.5015509670989,2.6152,79.836
4.885004,520.5410769984276,2.62596,80.036
4.906898,520.665669923268,2.63672,80.236
4.928084,520.7756554017477,2.64732,80.436
4.949797,521.0016411895617,2.65808,80.636
4.972439,521.2203232541954,2.66892,80.836
4.993747,521.3969015028484,2.67984,81.036
5.015137,521.5537167358373,2.69072,81.236
5.036018,521.7272875690633,2.70152,81.436
5.057157,521.7990359085402,2.71212,81.636
5.078691,521.9004287715137,2.72276,81.836
5.100068,522.103214497461,2.73352,82.036
5.119931,522.2819408999906,2.74416,82.236
5.139901,522.4615265640708,2.7548,82.436
5.159674,522.5831120734841,2.76536,82.636
5.180039,522.5534675499875,2.77544,82.836
5.198863,522.610608443104,2.78524,83.036
5.21754,522.7987867226905,2.79508,83.236
5.23646,523.0569948186528,2.80512,83.436
5.255449,523.3564474690452,2.8154,83.636
5.274986,523.6567593809881,2.8258,83.836
5.29473,523.8947748305106,2.83624,84.036
5.31444,523.9776935701458,2.84644,84.236
5.333508,524.06619750986,2.8566,84.436
5.352875,524.2165682812191,2.8668,84.636
5.372851,524.3729538834326,2.87692,84.836
5.393266,524.4829393619124,2.88696,85.036
5.412699,524.6204212100121,2.89704,85.236
5.431739,524.6943177033658,2.90696,85.436
5.45041,524.8287921360383,2.9168,85.636
5.469408,524.9761554919702,2.92656,85.836
5.488886,525.1355485096109,2.93628,86.036
5.509099,525.2820526039922,2.94608,86.236
5.52841,525.4087936827091,2.95576,86.436
5.547173,525.6425128244787,2.96552,86.636
5.566481,525.8336985194924,2.97532,86.836
5.58621,526.0102767681454,2.98516,87.036
5.606714,526.1795512936183,2.99516,87.236
5.626947,526.3514036037429,3.00516,87.436
5.647251,526.531848529374,3.01512,87.636
5.667941,526.6611673927426,3.02508,87.836
5.689086,526.773301025099,3.03508,88.036
5.709931,526.7410787169506,3.04472,88.236
5.7294,526.8261456104624,3.05436,88.436
5.749162,526.9473014891004,3.06392,88.636
5.768757,527.0340869057133,3.0734,88.836
5.789562,527.1561020459018,3.08292,89.036
5.808976,527.2712430936853,3.0924,89.236
5.828759,527.5307400819736,3.10204,89.436
5.849181,527.707747961402,3.11164,89.636
5.868939,527.8362075632202,3.1212,89.836
5.889699,527.9809931345003,3.13092,90.036
5.910628,528.1300750135334,3.1406,90.236
5.932176,528.2821643079938,3.15024,90.436
5.952596,528.3861349556192,3.15984,90.636
5.97343,528.3964460942267,3.16924,90.836
5.993227,528.388712740271,3.17848,91.036
6.014113,528.497409326425,3.18768,91.236
6.034569,528.5670095120254,3.19672,91.436
6.053459,528.6348911745247,3.20564,91.636
6.07323,528.7723730226244,3.21464,91.836
6.092316,528.8703288393954,3.22356,92.036
6.111992,529.0340181647892,3.2326,92.236
6.131923,529.2393816753881,3.24168,92.436
6.151436,529.4125228778388,3.2508,92.636
6.171507,529.5830862956375,3.26004,92.836
6.191302,529.6930717741174,3.26924,93.036
6.211469,529.805635037249,3.2784,93.236
6.231835,529.9220649773584,3.28752,93.436
6.251241,530.0505245791767,3.2966,93.636
6.271025,530.0453690098728,3.30544,93.836
6.289566,530.0260356249839,3.3142,94.036
6.309132,530.1570730114539,3.32304,94.236
6.329742,530.3001400596328,3.33188,94.436
6.348722,530.4144218458656,3.3406,94.636
6.367505,530.5119480318615,3.34928,94.836
6.38653,530.5854148944396,3.35796,95.036
6.405672,530.7383634504507,3.3668,95.236
6.425533,530.9029120373951,3.3756,95.436
6.445106,531.0150456697514,3.38444,95.636
6.464617,531.168853487313,3.39344,95.836
6.484284,531.2298610574072,3.40232,96.036
6.503706,531.3080538585141,3.41128,96.236
6.523974,531.4468245989397,3.4202,96.436
6.543492,531.5718471545554,3.42916,96.636
6.563381,531.5894620163432,3.43792,96.836
6.582405,531.6272695245706,3.44668,97.036
6.601247,531.7209290335885,3.4556,97.236
6.621903,531.9172702979059,3.4646,97.436
6.642342,532.0921300234579,3.4736,97.636
6.662324,532.1965303018586,3.48264,97.836
6.682318,532.2532415641998,3.49168,98.036
6.7022,532.3645159350054,3.50092,98.236
6.723168,532.5174644910165,3.51012,98.436
6.744032,532.6377611081036,3.5194,98.636
6.764983,532.7537614174379,3.5288,98.836
6.786015,532.7915689256653,3.53812,99.036
6.806986,532.8461320341299,3.54756,99.236
6.828008,532.9247544660119,3.55688,99.436
6.848835,532.9062803426735,3.56608,99.636
6.869279,532.862887634367,3.57508,99.836
6.889515,532.8826506500315,3.5842,100.036
6.91016,533.0407547753462,3.59352,100.236
6.931448,533.2332293626857,3.60292,100.436
6.953132,533.4029335189338,3.61236,100.636
6.973846,533.5112004743124,3.62188,100.836
6.99501,533.5717784136313,3.63136,101.036
7.015612,533.5249486591223,3.64056,101.236
7.0374,533.5137782589642,3.64964,101.436
7.058438,533.4837041046924,3.65856,101.636
7.078405,533.445896596465,3.66724,101.836
7.097931,533.4871411508949,3.676,102.036
7.116982,533.5081930588852,3.68464,102.236
7.136828,533.6486823224121,3.69336,102.436
7.156552,533.7225788157657,3.70184,102.636
7.17575,533.7419122006547,3.71024,102.836
7.194883,533.8209642633121,3.71868,103.036
7.213869,533.915912664656,3.72712,103.236
7.232599,534.0121499583258,3.73552,103.436
7.251883,534.1913059916308,3.744,103.636
7.270803,534.2694987927375,3.7524,103.836
7.289207,534.3777657481161,3.76084,104.036
7.308155,534.4774400879884,3.76932,104.236
7.327604,534.5461810120382,3.7778,104.436
7.346692,534.7382259686026,3.7864,104.636
7.366294,534.9242560943126,3.79512,104.836
7.386015,535.0119007724762,3.80384,105.036
7.405235,535.1008343429656,3.81264,105.236
7.424857,535.1618419130599,3.82152,105.436
7.444976,535.2602273606063,3.83032,105.636
7.465293,535.1708641593415,3.83876,105.836
7.484991,535.1145825277756,3.84712,106.036
7.503441,535.1369233280918,3.85556,106.236
7.522046,535.1893382826798,3.86404,106.436
7.541447,535.3560350235008,3.87272,106.636
7.561479,535.571280041932,3.88152,106.836
7.581446,535.6765395818833,3.89036,107.036
7.601441,535.7671916754741,3.89928,107.236
7.621436,535.7783620756322,3.9082,107.436
7.641387,535.7311026903479,3.91684,107.636
7.661553,535.7684805678001,3.92552,107.836
7.681163,535.8007028759484,3.93416,108.036
7.700934,535.8982290619441,3.94292,108.236
7.720438,536.0107923250758,3.9518,108.436
7.74067,536.2110002663711,3.96096,108.636
7.762162,536.3360228219867,3.97008,108.836
7.783007,536.3562154684265,3.97912,109.036
7.803874,536.3875785150242,3.98824,109.236
7.824516,536.3978896536316,3.9974,109.436
7.844873,536.435697161859,4.00652,109.636
7.866286,536.4082007922392,4.01548,109.836
7.887609,536.4344082695332,4.02448,110.036
7.908344,536.4936973165261,4.03348,110.236
7.928957,536.4558898082988,4.04244,110.436
7.949568,536.4988528858299,4.05144,110.636
7.969878,536.5856383024429,4.06036,110.836
7.990941,536.5310751939784,4.06916,111.036
8.01086,536.5370900248327,4.07788,111.236
8.030417,536.504438085909,4.08652,111.436
8.050398,536.5607197174747,4.09516,111.636
8.070095,536.610556887411,4.10372,111.836
8.09055,536.7519054124884,4.1124,112.036
8.110335,536.895831722218,4.12124,112.236
8.130683,537.0264394779126,4.1302,112.436
8.15134,537.1274027101109,4.13916,112.636
8.172522,537.1600546490346,4.14796,112.836
8.193479,537.1518916643037,4.15668,113.036
8.213028,537.179817664699,4.16544,113.236
8.233447,537.139862002595,4.17412,113.436
8.253179,537.1884102802052,4.18288,113.636
8.273681,537.3533884979249,4.19176,113.836
8.294699,537.3443662516434,4.20044,114.036
8.314954,537.3826033906461,4.20912,114.236
8.334947,537.3705737289374,4.2178,114.436
8.354814,537.3598329595545,4.22644,114.636
8.374507,537.3207365590011,4.2348,114.836
8.394134,537.240395604018,4.24296,115.036
8.412674,537.1957140033855,4.25104,115.236
8.43135,537.2330918808376,4.25916,115.436
8.449709,537.2588697273563,4.2672,115.636
8.468141,537.3778774521177,4.2754,115.836
8.487183,537.5140704078915,4.28352,116.036
8.505671,537.6309299787763,4.29168,116.236
8.523849,537.7177153953892,4.29984,116.436
8.542711,537.7709896115279,4.308,116.636
8.561292,537.8788269361311,4.31628,116.836
8.580434,538.0489607231546,4.32476,117.036
8.600717,538.177849955748,4.33328,117.236
8.619685,538.2775242956204,4.34184,117.436
8.638527,538.332087404085,4.35052,117.636
8.658051,538.3991098050335,4.35928,117.836
8.678097,538.3973912819323,4.368,118.036
8.697627,538.3415392811419,4.37656,118.236
8.717285,538.3385318657147,4.38516,118.436
8.735801,538.3204873731515,4.39376,118.636
8.755478,538.3591541429296,4.40252,118.836
8.774534,538.4446506672166,4.4114,119.036
8.794007,538.5211249452221,4.42028,119.236
8.81391,538.6036140540818,4.42924,119.436
8.833088,538.64228082386,4.43824,119.636
8.852915,538.6654808857269,4.44732,119.836
8.872312,538.7488292561372,4.45664,120.036
8.893472,538.8218664879403,4.46596,120.236
8.913679,538.8691258732246,4.4754,120.436
8.933742,538.9155259969582,4.485,120.636
8.953868,538.900059289047,4.49468,120.836
8.973785,538.7857775028142,4.50416,121.036
8.993787,538.7780441488585,4.51368,121.236
9.014529,538.7707404256782,4.52324,121.436
9.03437,538.7449625791595,4.5328,121.636
9.054561,538.7917923336685,4.5426,121.836
9.07445,538.8618221500443,4.55252,122.036
9.094669,538.9610668591413,4.56256,122.236
9.115537,538.9838372902328,4.57276,122.436
9.136057,538.9232593509139,4.58288,122.636
9.155808,538.8992000274964,4.59312,122.836
9.176229,538.906933381452,4.60336,123.036
9.196719,538.9266963971164,4.61372,123.236
9.216891,538.9434519973536,4.6242,123.436
9.237048,538.8377628266268,4.63456,123.636
9.25636,538.7754663642066,4.64484,123.836
9.275328,538.7862071335894,4.65528,124.036
9.295099,538.7642959640485,4.66568,124.236
9.315055,538.7965182721969,4.67624,124.436
9.334067,538.8218664879403,4.68696,124.636
9.353059,538.901348181373,4.69772,124.836
9.371891,538.8686962424492,4.70844,125.036
9.390265,538.8231553802663,4.71932,125.236
9.409119,538.8321776265478,4.7304,125.436
9.428243,538.9301334433188,4.74164,125.636
9.447129,538.9709483669734,4.75308,125.836
9.46542,538.9494668282078,4.76468,126.036
9.48357,538.9043555968002,4.7764,126.236
9.501573,538.9456001512301,4.78828,126.436
9.519685,538.9168148892841,4.80036,126.636
9.537907,538.8936148274173,4.81264,126.836
9.554983,538.8583851038418,4.8252,127.036
9.572686,538.8308887342218,4.83788,127.236
9.589556,538.7273477173717,4.85064,127.436
9.606878,538.6646216241762,4.86364,127.636
9.623782,538.6633327318502,4.87696,127.836
9.640342,538.6946957784479,4.89064,128.036
9.656576,538.6225178081957,4.904681,128.236
9.672395,538.5907251308225,4.91912,128.436
9.687818,538.5739695305854,4.93388,128.636
9.703032,538.3789171585939,4.94892,128.836
9.718177,538.2079241100198,4.96412,129.036
9.732533,538.1752721710961,4.9798,129.236
9.747121,538.1125460779007,4.99604,129.436
9.760804,538.1146942317772,5.01308,129.636
9.773835,538.0141606303542,5.03068,129.836
9.786588,537.7469302881103,5.048841,130.036
9.798533,537.618041055517,5.06772,130.236
9.81056,537.4131071756932,5.08732,130.436
9.821999,537.2717586506157,5.107761,130.636
9.832767,537.0242913240361,5.12908,130.836
9.843133,536.7630758126465,5.15128,131.036
9.853045,536.4692083623335,5.17444,131.236
9.861708,536.238496635991,5.19884,131.436
9.869875,535.7396953058542,5.22416,131.636
9.877806,535.4080203473135,5.2504,131.836
9.884687,535.0359600958936,5.27824,132.036
9.89138,534.4306103334794,5.3074,132.236
9.896681,533.8604902946408,5.33776,132.436
9.901851,533.1198068380035,5.36964,132.636
9.90647,532.3310047345312,5.40276,132.836
9.910746,531.5151358922143,5.43812,133.036
9.913468,530.2924067056771,5.47496,133.236
9.916306,529.0065217951692,5.51376,133.436
9.917873,527.2910061093497,5.55468,133.636
9.919458,525.3916084516966,5.59748,133.836
9.919704,522.9160759243507,5.64256,134.036
9.919719,519.6886895402091,5.69028,134.236
9.878137,492.9678034696981,5.70756,134.306
9.562061,450.2186820646337,5.70904,134.31
8.876887,396.74296909236205,5.71172,134.314
7.978713,338.00187319018033,5.71528,134.318
6.974305,278.98753211490043,5.71904,134.322
5.94876,222.76441626066563,5.72264,134.326
4.965713,171.54336263415223,5.72628,134.33
4.502182,148.19976112528892,5.72808,134.332